Workbook

Sheet Port Number
A1: BRAKE | B1: 0
A2: BILBAO | B2: 1
A3: ROTTERDAM | B3: 2
A4: CARTAGENA | B4: 3
A5: LIVERPOOL | B5: 4
A6: ANTWERP | B6: 5
A7: ZEEBRUGGE | B7: 6
A8: HAMBURG | B8: 7
A9: TALLINN | B9: 8
A10: ALGECIRAS | B10: 9
A11: HUELVA | B11: 10
A12: LA PALLICE | B12: 11
... A39: GENOA | B39: 38

Sheet Distance within the ECA
B1: BRAKE | E1: BILBAO | H1: ROTTERDAM | K1: CARTAGENA | N1: LIVERPOOL | Q1: ANTWERP | T1: ZEEBRUGGE | W1: HAMBURG | Z1: TALLINN | AC1: ALGECIRAS | AF1: HUELVA | AI1: LA PALLICE | AL1: MONTOIR DE BRETAGNE | AO1: DUNKIRK | AR1: TEESPORT | AU1: VLISSINGEN | AX1: GDANSK | BA1: MO I RANA | BD1: STAVANGER | BG1: LISBON | BJ1: SETUBAL | BM1: ORESUND | BP1: MALMO | BS1: HELSINGBORG | BV1: SINES | BY1: TILBURY | CB1: KLAIPEDA | CE1: FALMOUTH | CH1: LAS PALMAS | CK1: SANTANDER | CN1: VIGO | CQ1: EMDEN | CT1: CADIZ | CW1: LA SPEZIA | CZ1: THISVI | DC1: VADO LIGURE | DF1: RAVENNA | DI1: ANCONA | DL1: GENOA
A2: BRAKE | B2: 0 | C2: 0 | D2: 0 | E2: 637 | F2: 610 | G2: 536 | H2: 252 | I2: 255 | J2: 250 | K2: 637 | L2: 609 | M2: 536 | N2: 609 | O2: 571 | P2: 536 | Q2: 323 | R2: 323 | S2: 323 | T2: 296 | U2: 296 | V2: 296 | W2: 117 | X2: 117 | Y2: 117 | Z2: 750 | AA2: 750 | AB2: 750 | AC2: 637 | AD2: 609 | AE2: 536 | AF2: 637 | AG2: 609 | AH2: 536 | AI2: 637 | AJ2: 609 | AK2: 536 | AL2: 637 | AM2: 609 | AN2: 536 | AO2: 327 | AP2: 327 | AQ2: 327 | AR2: 388 | AS2: 383 | AT2: 378 | AU2: 305 | AV2: 300 | AW2: 297 | AX2: 495 | AY2: 490 | AZ2: 487 | BA2: 576 | BB2: 543 | BC2: 536 | BD2: 385 | BE2: 382 | BF2: 379 | BG2: 637 | BH2: 609 | BI2: 536 | BJ2: 637 | BK2: 609 | BL2: 536 | BM2: 405 | BN2: 400 | BO2: 396 | BP2: 305 | BQ2: 300 | BR2: 293 | BS2: 320 | BT2: 315 | BU2: 313 | BV2: 637 | BW2: 609 | BX2: 536 | BY2: 370 | BZ2: 366 | CA2: 364 | CB2: 540 | CC2: 536 | CD2: 532 | CE2: 612 | CF2: 609 | CG2: 560 | CH2: 637 | CI2: 609 | CJ2: 536 | CK2: 637 | CL2: 609 | CM2: 536 | CN2: 637 | CO2: 609 | CP2: 536 | CQ2: 135 | CR2: 130 | CS2: 127 | CT2: 637 | CU2: 609 | CV2: 536 | CW2: 637 | CX2: 609 | CY2: 536 | CZ2: 637 | DA2: 609 | DB2: 536 | DC2: 637 | DD2: 609 | DE2: 536 | DF2: 637 | DG2: 609 | DH2: 536 | DI2: 637 | DJ2: 609 | DK2: 536 | DL2: 637 | DM2: 609 | DN2: 536
A3: BILBAO | B3: =E2 -> 637 | C3: =F2 -> 610 | D3: =G2 -> 536 | E3: 0 | F3: 0 | G3: 0 | H3: 405 | I3: 388 | J3: 378 | K3: 0 | L3: 0 | M3: 0 | N3: 0 | O3: 0 | P3: 0 | Q3: 403 | R3: 385 | S3: 375 | T3: 367 | U3: 349 | V3: 339 | W3: 674 | X3: 657 | Y3: 647 | Z3: 1307 | AA3: 1280 | AB3: 1085 | AC3: 0 | AD3: 0 | AE3: 0 | AF3: 0 | AG3: 0 | AH3: 0 | AI3: 0 | AJ3: 0 | AK3: 0 | AL3: 0 | AM3: 0 | AN3: 0 | AO3: 337 | AP3: 320 | AQ3: 309 | AR3: 586 | AS3: 560 | AT3: 295 | AU3: 377 | AV3: 361 | AW3: 350 | AX3: 1043 | AY3: 1017 | AZ3: 901 | BA3: 961 | BB3: 936 | BC3: 0 | BD3: 805 | BE3: 779 | BF3: 210 | BG3: 0 | BH3: 0 | BI3: 0 | BJ3: 0 | BK3: 0 | BL3: 0 | BM3: 818 | BN3: 791 | BO3: 173 | BP3: 849 | BQ3: 822 | BR3: 562 | BS3: 871 | BT3: 843 | BU3: 533 | BV3: 0 | BW3: 0 | BX3: 0 | BY3: 379 | BZ3: 361 | CA3: 352 | CB3: 1088 | CC3: 950 | CD3: 868 | CE3: 54 | CF3: 36 | CG3: 23 | CH3: 0 | CI3: 0 | CJ3: 0 | CK3: 0 | CL3: 0 | CM3: 0 | CN3: 0 | CO3: 0 | CP3: 0 | CQ3: 575 | CR3: 549 | CS3: 505 | CT3: 0 | CU3: 0 | CV3: 0 | CW3: 0 | CX3: 0 | CY3: 0 | CZ3: 0 | DA3: 0 | DB3: 0 | DC3: 0 | DD3: 0 | DE3: 0 | DF3: 0 | DG3: 0 | DH3: 0 | DI3: 0 | DJ3: 0 | DK3: 0 | DL3: 0 | DM3: 0 | DN3: 0
A4: ROTTERDAM | B4: =H2 -> 252 | C4: =I2 -> 255 | D4: =J2 -> 250 | E4: =H3 -> 405 | F4: =I3 -> 388 | G4: =J3 -> 378 | H4: 0 | I4: 0 | J4: 0 | K4: 405 | L4: 387 | M4: 378 | N4: 385 | O4: 381 | P4: 378 | Q4: 75 | R4: 73 | S4: 72 | T4: 60 | U4: 58 | V4: 56 | W4: 290 | X4: 288 | Y4: 287 | Z4: 925 | AA4: 923 | AB4: 920 | AC4: 405 | AD4: 388 | AE4: 378 | AF4: 405 | AG4: 389 | AH4: 378 | AI4: 405 | AJ4: 390 | AK4: 378 | AL4: 405 | AM4: 390 | AN4: 378 | AO4: 95 | AP4: 93 | AQ4: 92 | AR4: 275 | AS4: 273 | AT4: 271 | AU4: 60 | AV4: 58 | AW4: 57 | AX4: 660 | AY4: 658 | AZ4: 656 | BA4: 605 | BB4: 603 | BC4: 378 | BD4: 445 | BE4: 443 | BF4: 442 | BG4: 405 | BH4: 387 | BI4: 378 | BJ4: 405 | BK4: 387 | BL4: 378 | BM4: 460 | BN4: 458 | BO4: 457 | BP4: 465 | BQ4: 463 | BR4: 462 | BS4: 485 | BT4: 483 | BU4: 482 | BV4: 405 | BW4: 389 | BX4: 378 | BY4: 150 | BZ4: 148 | CA4: 145 | CB4: 705 | CC4: 702 | CD4: 701 | CE4: 380 | CF4: 379 | CG4: 376 | CH4: 405 | CI4: 388 | CJ4: 378 | CK4: 405 | CL4: 388 | CM4: 378 | CN4: 405 | CO4: 388 | CP4: 378 | CQ4: 190 | CR4: 189 | CS4: 188 | CT4: 405 | CU4: 388 | CV4: 378 | CW4: 405 | CX4: 387 | CY4: 378 | CZ4: 405 | DA4: 387 | DB4: 378 | DC4: 405 | DD4: 387 | DE4: 378 | DF4: 405 | DG4: 387 | DH4: 378 | DI4: 405 | DJ4: 387 | DK4: 378 | DL4: 405 | DM4: 387 | DN4: 378
A5: CARTAGENA | B5: =K2 -> 637 | C5: =L2 -> 609 | D5: =M2 -> 536 | E5: =K3 -> 0 | F5: =L3 -> 0 | G5: =M3 -> 0 | H5: =K4 -> 405 | I5: =L4 -> 387 | J5: =M4 -> 378 | K5: 0 | L5: 0 | M5: 0 | N5: 0 | O5: 0 | P5: 0 | Q5: 403 | R5: 385 | S5: 375 | T5: 367 | U5: 348 | V5: 339 | W5: 674 | X5: 658 | Y5: 646 | Z5: 1307 | AA5: 1279 | AB5: 1085 | AC5: 0 | AD5: 0 | AE5: 0 | AF5: 0 | AG5: 0 | AH5: 0 | AI5: 0 | AJ5: 0 | AK5: 0 | AL5: 0 | AM5: 0 | AN5: 0 | AO5: 337 | AP5: 320 | AQ5: 309 | AR5: 586 | AS5: 560 | AT5: 295 | AU5: 377 | AV5: 359 | AW5: 350 | AX5: 1043 | AY5: 1016 | AZ5: 902 | BA5: 205 | BB5: 90 | BC5: 0 | BD5: 805 | BE5: 308 | BF5: 210 | BG5: 0 | BH5: 0 | BI5: 0 | BJ5: 0 | BK5: 0 | BL5: 0 | BM5: 818 | BN5: 284 | BO5: 173 | BP5: 849 | BQ5: 631 | BR5: 562 | BS5: 869 | BT5: 602 | BU5: 533 | BV5: 0 | BW5: 0 | BX5: 0 | BY5: 379 | BZ5: 362 | CA5: 351 | CB5: 1088 | CC5: 1061 | CD5: 868 | CE5: 28 | CF5: 23 | CG5: 0 | CH5: 0 | CI5: 0 | CJ5: 0 | CK5: 0 | CL5: 0 | CM5: 0 | CN5: 0 | CO5: 0 | CP5: 0 | CQ5: 575 | CR5: 559 | CS5: 548 | CT5: 0 | CU5: 0 | CV5: 0 | CW5: 0 | CX5: 0 | CY5: 0 | CZ5: 0 | DA5: 0 | DB5: 0 | DC5: 0 | DD5: 0 | DE5: 0 | DF5: 0 | DG5: 0 | DH5: 0 | DI5: 0 | DJ5: 0 | DK5: 0 | DL5: 0 | DM5: 0 | DN5: 0
A6: LIVERPOOL | B6: =N2 -> 609 | C6: =O2 -> 571 | D6: =P2 -> 536 | E6: =N3 -> 0 | F6: =O3 -> 0 | G6: =P3 -> 0 | H6: =N4 -> 385 | I6: =O4 -> 381 | J6: =P4 -> 378 | K6: =N5 -> 0 | L6: =O5 -> 0 | M6: =P5 -> 0 | N6: 0 | O6: 0 | P6: 0 | Q6: 378 | R6: 377 | S6: 375 | T6: 341 | U6: 340 | V6: 339 | W6: 649 | X6: 646 | Y6: 564 | Z6: 1652 | AA6: 1154 | AB6: 1085 | AC6: 0 | AD6: 0 | AE6: 0 | AF6: 0 | AG6: 0 | AH6: 0 | AI6: 0 | AJ6: 0 | AK6: 0 | AL6: 0 | AM6: 0 | AN6: 0 | AO6: 309 | AP6: 305 | AQ6: 301 | AR6: 295 | AS6: 295 | AT6: 295 | AU6: 350 | AV6: 350 | AW6: 350 | AX6: 1016 | AY6: 901 | AZ6: 832 | BA6: 205 | BB6: 125 | BC6: 0 | BD6: 311 | BE6: 307 | BF6: 210 | BG6: 0 | BH6: 0 | BI6: 0 | BJ6: 0 | BK6: 0 | BL6: 0 | BM6: 0 | BN6: 0 | BO6: 0 | BP6: 822 | BQ6: 631 | BR6: 562 | BS6: 608 | BT6: 602 | BU6: 533 | BV6: 0 | BW6: 0 | BX6: 0 | BY6: 356 | BZ6: 355 | CA6: 351 | CB6: 1061 | CC6: 937 | CD6: 868 | CE6: 23 | CF6: 12 | CG6: 0 | CH6: 0 | CI6: 0 | CJ6: 0 | CK6: 0 | CL6: 0 | CM6: 0 | CN6: 0 | CO6: 0 | CP6: 0 | CQ6: 555 | CR6: 548 | CS6: 505 | CT6: 0 | CU6: 0 | CV6: 0 | CW6: 0 | CX6: 0 | CY6: 0 | CZ6: 0 | DA6: 0 | DB6: 0 | DC6: 0 | DD6: 0 | DE6: 0 | DF6: 0 | DG6: 0 | DH6: 0 | DI6: 0 | DJ6: 0 | DK6: 0 | DL6: 0 | DM6: 0 | DN6: 0
A7: ANTWERP | B7: =Q2 -> 323 | C7: =R2 -> 323 | D7: =S2 -> 323 | E7: =Q3 -> 403 | F7: =R3 -> 385 | G7: =S3 -> 375 | H7: =Q4 -> 75 | I7: =R4 -> 73 | J7: =S4 -> 72 | K7: =Q5 -> 403 | L7: =R5 -> 385 | M7: =S5 -> 375 | N7: =Q6 -> 378 | O7: =R6 -> 377 | P7: =S6 -> 375 | Q7: 0 | R7: 0 | S7: 0 | T7: 48 | U7: 48 | V7: 48 | W7: 359 | X7: 359 | Y7: 359 | Z7: 993 | AA7: 993 | AB7: 993 | AC7: 403 | AD7: 386 | AE7: 375 | AF7: 403 | AG7: 388 | AH7: 375 | AI7: 403 | AJ7: 386 | AK7: 375 | AL7: 403 | AM7: 389 | AN7: 375 | AO7: 89 | AP7: 89 | AQ7: 89 | AR7: 314 | AS7: 314 | AT7: 314 | AU7: 26 | AV7: 26 | AW7: 26 | AX7: 729 | AY7: 729 | AZ7: 729 | BA7: 670 | BB7: 669 | BC7: 375 | BD7: 510 | BE7: 510 | BF7: 510 | BG7: 403 | BH7: 385 | BI7: 375 | BJ7: 403 | BK7: 388 | BL7: 375 | BM7: 525 | BN7: 525 | BO7: 525 | BP7: 535 | BQ7: 535 | BR7: 535 | BS7: 555 | BT7: 555 | BU7: 555 | BV7: 403 | BW7: 385 | BX7: 375 | BY7: 153 | BZ7: 153 | CA7: 153 | CB7: 774 | CC7: 774 | CD7: 774 | CE7: 378 | CF7: 377 | CG7: 374 | CH7: 403 | CI7: 387 | CJ7: 375 | CK7: 403 | CL7: 386 | CM7: 375 | CN7: 403 | CO7: 385 | CP7: 375 | CQ7: 261 | CR7: 261 | CS7: 261 | CT7: 403 | CU7: 387 | CV7: 375 | CW7: 403 | CX7: 385 | CY7: 375 | CZ7: 403 | DA7: 386 | DB7: 375 | DC7: 403 | DD7: 385 | DE7: 375 | DF7: 403 | DG7: 385 | DH7: 375 | DI7: 403 | DJ7: 385 | DK7: 375 | DL7: 403 | DM7: 386 | DN7: 375
A8: ZEEBRUGGE | B8: =T2 -> 296 | C8: =U2 -> 296 | D8: =V2 -> 296 | E8: =T3 -> 367 | F8: =U3 -> 349 | G8: =V3 -> 339 | H8: =T4 -> 60 | I8: =U4 -> 58 | J8: =V4 -> 56 | K8: =T5 -> 367 | L8: =U5 -> 348 | M8: =V5 -> 339 | N8: =T6 -> 341 | O8: =U6 -> 340 | P8: =V6 -> 339 | Q8: =T7 -> 48 | R8: =U7 -> 48 | S8: =V7 -> 48 | T8: 0 | U8: 0 | V8: 0 | W8: 333 | X8: 333 | Y8: 333 | Z8: 966 | AA8: 966 | AB8: 966 | AC8: 367 | AD8: 350 | AE8: 339 | AF8: 367 | AG8: 350 | AH8: 339 | AI8: 367 | AJ8: 353 | AK8: 339 | AL8: 352 | AM8: 339 | AN8: 367 | AO8: 53 | AP8: 53 | AQ8: 53 | AR8: 283 | AS8: 283 | AT8: 283 | AU8: 17 | AV8: 17 | AW8: 17 | AX8: 702 | AY8: 702 | AZ8: 702 | BA8: 642 | BB8: 640 | BC8: 339 | BD8: 483 | BE8: 483 | BF8: 483 | BG8: 367 | BH8: 350 | BI8: 339 | BJ8: 367 | BK8: 351 | BL8: 339 | BM8: 497 | BN8: 497 | BO8: 497 | BP8: 509 | BQ8: 509 | BR8: 509 | BS8: 528 | BT8: 528 | BU8: 528 | BV8: 367 | BW8: 351 | BX8: 339 | BY8: 118 | BZ8: 118 | CA8: 118 | CB8: 747 | CC8: 747 | CD8: 747 | CE8: 342 | CF8: 340 | CG8: 338 | CH8: 367 | CI8: 351 | CJ8: 339 | CK8: 367 | CL8: 351 | CM8: 339 | CN8: 367 | CO8: 351 | CP8: 339 | CQ8: 234 | CR8: 234 | CS8: 234 | CT8: 367 | CU8: 351 | CV8: 339 | CW8: 367 | CX8: 351 | CY8: 339 | CZ8: 367 | DA8: 351 | DB8: 339 | DC8: 367 | DD8: 351 | DE8: 339 | DF8: 367 | DG8: 351 | DH8: 339 | DI8: 367 | DJ8: 351 | DK8: 339 | DL8: 367 | DM8: 351 | DN8: 339
A9: HAMBURG | B9: =W2 -> 117 | C9: =X2 -> 117 | D9: =Y2 -> 117 | E9: =W3 -> 674 | F9: =X3 -> 657 | G9: =Y3 -> 647 | H9: =W4 -> 290 | I9: =X4 -> 288 | J9: =Y4 -> 287 | K9: =W5 -> 674 | L9: =X5 -> 658 | M9: =Y5 -> 646 | N9: =W6 -> 649 | O9: =X6 -> 646 | P9: =Y6 -> 564 | Q9: =W7 -> 359 | R9: =X7 -> 359 | S9: =Y7 -> 359 | T9: =W8 -> 333 | U9: =X8 -> 333 | V9: =Y8 -> 333 | W9: 0 | X9: 0 | Y9: 0 | Z9: 701 | AA9: 701 | AB9: 701 | AC9: 674 | AD9: 658 | AE9: 646 | AF9: 674 | AG9: 658 | AH9: 646 | AI9: 674 | AJ9: 658 | AK9: 646 | AL9: 674 | AM9: 658 | AN9: 646 | AO9: 364 | AP9: 364 | AQ9: 364 | AR9: 413 | AS9: 413 | AT9: 413 | AU9: 334 | AV9: 334 | AW9: 334 | AX9: 438 | AY9: 438 | AZ9: 438 | BA9: 649 | BB9: 562 | BC9: 378 | BD9: 398 | BE9: 398 | BF9: 398 | BG9: 674 | BH9: 657 | BI9: 646 | BJ9: 674 | BK9: 658 | BL9: 646 | BM9: 415 | BN9: 415 | BO9: 415 | BP9: 244 | BQ9: 244 | BR9: 244 | BS9: 264 | BT9: 264 | BU9: 264 | BV9: 674 | BW9: 657 | BX9: 646 | BY9: 401 | BZ9: 401 | CA9: 401 | CB9: 483 | CC9: 483 | CD9: 483 | CE9: 649 | CF9: 647 | CG9: 646 | CH9: 674 | CI9: 659 | CJ9: 646 | CK9: 674 | CL9: 659 | CM9: 646 | CN9: 674 | CO9: 659 | CP9: 646 | CQ9: 164 | CR9: 164 | CS9: 164 | CT9: 674 | CU9: 658 | CV9: 646 | CW9: 674 | CX9: 658 | CY9: 646 | CZ9: 674 | DA9: 658 | DB9: 646 | DC9: 674 | DD9: 658 | DE9: 646 | DF9: 674 | DG9: 658 | DH9: 646 | DI9: 674 | DJ9: 658 | DK9: 646 | DL9: 674 | DM9: 658 | DN9: 646
A10: TALLINN | B10: =Z2 -> 750 | C10: =AA2 -> 750 | D10: =AB2 -> 750 | E10: =Z3 -> 1307 | F10: =AA3 -> 1280 | G10: =AB3 -> 1085 | H10: =Z4 -> 925 | I10: =AA4 -> 923 | J10: =AB4 -> 920 | K10: =Z5 -> 1307 | L10: =AA5 -> 1279 | M10: =AB5 -> 1085 | N10: =Z6 -> 1652 | O10: =AA6 -> 1154 | P10: =AB6 -> 1085 | Q10: =Z7 -> 993 | R10: =AA7 -> 993 | S10: =AB7 -> 993 | T10: =Z8 -> 966 | U10: =AA8 -> 966 | V10: =AB8 -> 966 | W10: =Z9 -> 701 | X10: =AA9 -> 701 | Y10: =AB9 -> 701 | Z10: 0 | AA10: 0 | AB10: 0 | AC10: 1307 | AD10: 1290 | AE10: 1279 | AF10: 1307 | AG10: 1290 | AH10: 1279 | AI10: 1307 | AJ10: 1279 | AK10: 1085 | AL10: 1307 | AM10: 1291 | AN10: 1279 | AO10: 997 | AP10: 997 | AQ10: 997 | AR10: 1040 | AS10: 1046 | AT10: 1046 | AU10: 967 | AV10: 967 | AW10: 967 | AX10: 414 | AY10: 414 | AZ10: 414 | BA10: 1085 | BB10: 1085 | BC10: 1085 | BD10: 921 | BE10: 921 | BF10: 921 | BG10: 1307 | BH10: 1290 | BI10: 1279 | BJ10: 1307 | BK10: 1292 | BL10: 1279 | BM10: 938 | BN10: 938 | BO10: 938 | BP10: 533 | BQ10: 533 | BR10: 533 | BS10: 555 | BT10: 555 | BU10: 555 | BV10: 1307 | BW10: 1290 | BX10: 1279 | BY10: 1046 | BZ10: 1046 | CA10: 1046 | CB10: 337 | CC10: 337 | CD10: 337 | CE10: 1292 | CF10: 1282 | CG10: 1279 | CH10: 1307 | CI10: 1291 | CJ10: 1279 | CK10: 1307 | CL10: 1291 | CM10: 1279 | CN10: 1307 | CO10: 1292 | CP10: 1279 | CQ10: 797 | CR10: 797 | CS10: 797 | CT10: 1307 | CU10: 1291 | CV10: 1279 | CW10: 1307 | CX10: 1290 | CY10: 1279 | CZ10: 1307 | DA10: 1292 | DB10: 1280 | DC10: 1307 | DD10: 1293 | DE10: 1279 | DF10: 1307 | DG10: 1292 | DH10: 1279 | DI10: 1307 | DJ10: 1292 | DK10: 1279 | DL10: 1307 | DM10: 1291 | DN10: 1279
A11: ALGECIRAS | B11: =AC2 -> 637 | C11: =AD2 -> 609 | D11: =AE2 -> 536 | E11: =AC3 -> 0 | F11: =AD3 -> 0 | G11: =AE3 -> 0 | H11: =AC4 -> 405 | I11: =AD4 -> 388 | J11: =AE4 -> 378 | K11: =AC5 -> 0 | L11: =AD5 -> 0 | M11: =AE5 -> 0 | N11: =AC6 -> 0 | O11: =AD6 -> 0 | P11: =AE6 -> 0 | Q11: =AC7 -> 403 | R11: =AD7 -> 386 | S11: =AE7 -> 375 | T11: =AC8 -> 367 | U11: =AD8 -> 350 | V11: =AE8 -> 339 | W11: =AC9 -> 674 | X11: =AD9 -> 658 | Y11: =AE9 -> 646 | Z11: =AC10 -> 1307 | AA11: =AD10 -> 1290 | AB11: =AE10 -> 1279 | AC11: 0 | AD11: 0 | AE11: 0 | AF11: 0 | AG11: 0 | AH11: 0 | AI11: 0 | AJ11: 0 | AK11: 0 | AL11: 0 | AM11: 0 | AN11: 0 | AO11: 337 | AP11: 322 | AQ11: 309 | AR11: 586 | AS11: 572 | AT11: 559 | AU11: 377 | AV11: 362 | AW11: 350 | AX11: 1043 | AY11: 1029 | AZ11: 1016 | BA11: 933 | BB11: 205 | BC11: 0 | BD11: 805 | BE11: 778 | BF11: 210 | BG11: 0 | BH11: 0 | BI11: 0 | BJ11: 0 | BK11: 0 | BL11: 0 | BM11: 818 | BN11: 791 | BO11: 173 | BP11: 849 | BQ11: 822 | BR11: 562 | BS11: 869 | BT11: 842 | BU11: 533 | BV11: 0 | BW11: 0 | BX11: 0 | BY11: 379 | BZ11: 363 | CA11: 351 | CB11: 1088 | CC11: 1061 | CD11: 868 | CE11: 28 | CF11: 17 | CG11: 0 | CH11: 0 | CI11: 0 | CJ11: 0 | CK11: 0 | CL11: 0 | CM11: 0 | CN11: 0 | CO11: 0 | CP11: 0 | CQ11: 575 | CR11: 561 | CS11: 548 | CT11: 0 | CU11: 0 | CV11: 0 | CW11: 0 | CX11: 0 | CY11: 0 | CZ11: 0 | DA11: 0 | DB11: 0 | DC11: 0 | DD11: 0 | DE11: 0 | DF11: 0 | DG11: 0 | DH11: 0 | DI11: 0 | DJ11: 0 | DK11: 0 | DL11: 0 | DM11: 0 | DN11: 0
A12: HUELVA | B12: =AF2 -> 637 | C12: =AG2 -> 609 | D12: =AH2 -> 536 | E12: =AF3 -> 0 | F12: =AG3 -> 0 | G12: =AH3 -> 0 | H12: =AF4 -> 405 | I12: =AG4 -> 389 | J12: =AH4 -> 378 | K12: =AF5 -> 0 | L12: =AG5 -> 0 | M12: =AH5 -> 0 | N12: =AF6 -> 0 | O12: =AG6 -> 0 | P12: =AH6 -> 0 | Q12: =AF7 -> 403 | R12: =AG7 -> 388 | S12: =AH7 -> 375 | T12: =AF8 -> 367 | U12: =AG8 -> 350 | V12: =AH8 -> 339 | W12: =AF9 -> 674 | X12: =AG9 -> 658 | Y12: =AH9 -> 646 | Z12: =AF10 -> 1307 | AA12: =AG10 -> 1290 | AB12: ='Distance outside the ECA'!AG10 -> 909 | AC12: =AF11 -> 0 | AD12: =AG11 -> 0 | AE12: =AH11 -> 0 | AF12: 0 | AG12: 0 | AH12: 0 | AI12: 0 | AJ12: 0 | AK12: 0 | AL12: 0 | AM12: 0 | AN12: 0 | AO12: 337 | AP12: 321 | AQ12: 309 | AR12: 586 | AS12: 559 | AT12: 295 | AU12: 377 | AV12: 361 | AW12: 350 | AX12: 1043 | AY12: 1029 | AZ12: 1016 | BA12: 205 | BB12: 108 | BC12: 0 | BD12: 805 | BE12: 778 | BF12: 210 | BG12: 0 | BH12: 0 | BI12: 0 | BJ12: 0 | BK12: 0 | BL12: 0 | BM12: 818 | BN12: 791 | BO12: 173 | BP12: 849 | BQ12: 822 | BR12: 562 | BS12: 871 | BT12: 842 | BU12: 533 | BV12: 0 | BW12: 0 | BX12: 0 | BY12: 379 | BZ12: 363 | CA12: 351 | CB12: 1088 | CC12: 1061 | CD12: 868 | CE12: 28 | CF12: 21 | CG12: 960 | CH12: 0 | CI12: 0 | CJ12: 0 | CK12: 0 | CL12: 0 | CM12: 0 | CN12: 0 | CO12: 0 | CP12: 0 | CQ12: 576 | CR12: 548 | CS12: 505 | CT12: 0 | CU12: 0 | CV12: 0 | CW12: 0 | CX12: 0 | CY12: 0 | CZ12: 0 | DA12: 0 | DB12: 0 | DC12: 0 | DD12: 0 | DE12: 0 | DF12: 0 | DG12: 0 | DH12: 0 | DI12: 0 | DJ12: 0 | DK12: 0 | DL12: 0 | DM12: 0 | DN12: 0
A13: LA PALLICE | B13: =AI2 -> 637 | C13: =AJ2 -> 609 | D13: =AK2 -> 536 | E13: =AI3 -> 0 | F13: =AJ3 -> 0 | G13: =AK3 -> 0 | H13: =AI4 -> 405 | I13: =AJ4 -> 390 | J13: =AK4 -> 378 | K13: =AI5 -> 0 | L13: =AJ5 -> 0 | M13: =AK5 -> 0 | N13: =AI6 -> 0 | O13: =AJ6 -> 0 | P13: =AK6 -> 0 | Q13: =AI7 -> 403 | R13: =AJ7 -> 386 | S13: =AK7 -> 375 | T13: =AI8 -> 367 | U13: =AJ8 -> 353 | V13: =AK8 -> 339 | W13: =AI9 -> 674 | X13: =AJ9 -> 658 | Y13: =AK9 -> 646 | Z13: =AI10 -> 1307 | AA13: =AJ10 -> 1279 | AB13: =AK10 -> 1085 | AC13: =AI11 -> 0 | AD13: =AJ11 -> 0 | AE13: =AK11 -> 0 | AF13: =AI12 -> 0 | AG13: =AJ12 -> 0 | AH13: =AK12 -> 0 | AI13: 0 | AJ13: 0 | AK13: 0 | AL13: 0 | AM13: 0 | AN13: 0 | AO13: 337 | AP13: 321 | AQ13: 309 | AR13: 586 | AS13: 559 | AT13: 295 | AU13: 377 | AV13: 363 | AW13: 350 | AX13: 1263 | AY13: 1236 | AZ13: 901 | BA13: 933 | BB13: 240 | BC13: 0 | BD13: 778 | BE13: 307 | BF13: 210 | BG13: 0 | BH13: 0 | BI13: 0 | BJ13: 0 | BK13: 0 | BL13: 0 | BM13: 791 | BN13: 291 | BO13: 173 | BP13: 822 | BQ13: 631 | BR13: 562 | BS13: 842 | BT13: 602 | BU13: 533 | BV13: 0 | BW13: 0 | BX13: 0 | BY13: 379 | BZ13: 363 | CA13: 352 | CB13: 1264 | CC13: 937 | CD13: 868 | CE13: 54 | CF13: 32 | CG13: 0 | CH13: 0 | CI13: 0 | CJ13: 0 | CK13: 0 | CL13: 0 | CM13: 0 | CN13: 0 | CO13: 0 | CP13: 0 | CQ13: 575 | CR13: 548 | CS13: 505 | CT13: 0 | CU13: 0 | CV13: 0 | CW13: 0 | CX13: 0 | CY13: 0 | CZ13: 0 | DA13: 0 | DB13: 0 | DC13: 0 | DD13: 0 | DE13: 0 | DF13: 0 | DG13: 0 | DH13: 0 | DI13: 0 | DJ13: 0 | DK13: 0 | DL13: 0 | DM13: 0 | DN13: 0
A14: MONTOIR DE BRETAGNE | B14: =AL2 -> 637 | C14: =AM2 -> 609 | D14: =AN2 -> 536 | E14: =AL3 -> 0 | F14: =AM3 -> 0 | G14: =AN3 -> 0 | H14: =AL4 -> 405 | I14: =AM4 -> 390 | J14: =AN4 -> 378 | K14: =AL5 -> 0 | L14: =AM5 -> 0 | M14: =AN5 -> 0 | N14: =AL6 -> 0 | O14: =AM6 -> 0 | P14: =AN6 -> 0 | Q14: =AL7 -> 403 | R14: =AM7 -> 389 | S14: =AN7 -> 375 | T14: =AL8 -> 352 | U14: =AM8 -> 339 | V14: =AN8 -> 367 | W14: =AL9 -> 674 | X14: =AM9 -> 658 | Y14: =AN9 -> 646 | Z14: =AL10 -> 1307 | AA14: =AM10 -> 1291 | AB14: =AN10 -> 1279 | AC14: =AL11 -> 0 | AD14: =AM11 -> 0 | AE14: =AN11 -> 0 | AF14: =AL12 -> 0 | AG14: =AM12 -> 0 | AH14: =AN12 -> 0 | AI14: =AL13 -> 0 | AJ14: =AM13 -> 0 | AK14: =AN13 -> 0 | AL14: 0 | AM14: 0 | AN14: 0 | AO14: 337 | AP14: 323 | AQ14: 309 | AR14: 586 | AS14: 559 | AT14: 295 | AU14: 377 | AV14: 364 | AW14: 350 | AX14: 1255 | AY14: 1229 | AZ14: 901 | BA14: 934 | BB14: 307 | BC14: 0 | BD14: 805 | BE14: 307 | BF14: 210 | BG14: 0 | BH14: 0 | BI14: 0 | BJ14: 0 | BK14: 0 | BL14: 0 | BM14: 799 | BN14: 292 | BO14: 173 | BP14: 984 | BQ14: 631 | BR14: 562 | BS14: 955 | BT14: 602 | BU14: 533 | BV14: 0 | BW14: 0 | BX14: 0 | BY14: 379 | BZ14: 364 | CA14: 352 | CB14: 1290 | CC14: 937 | CD14: 868 | CE14: 54 | CF14: 22 | CG14: 0 | CH14: 0 | CI14: 0 | CJ14: 0 | CK14: 0 | CL14: 0 | CM14: 0 | CN14: 0 | CO14: 0 | CP14: 0 | CQ14: 575 | CR14: 562 | CS14: 548 | CT14: 0 | CU14: 0 | CV14: 0 | CW14: 0 | CX14: 0 | CY14: 0 | CZ14: 0 | DA14: 0 | DB14: 0 | DC14: 0 | DD14: 0 | DE14: 0 | DF14: 0 | DG14: 0 | DH14: 0 | DI14: 0 | DJ14: 0 | DK14: 0 | DL14: 0 | DM14: 0 | DN14: 0
A15: DUNKIRK | B15: =AO2 -> 327 | C15: =AP2 -> 327 | D15: =AQ2 -> 327 | E15: =AO3 -> 337 | F15: =AP3 -> 320 | G15: =AQ3 -> 309 | H15: =AO4 -> 95 | I15: =AP4 -> 93 | J15: =AQ4 -> 92 | K15: =AO5 -> 337 | L15: =AP5 -> 320 | M15: =AQ5 -> 309 | N15: =AO6 -> 309 | O15: =AP6 -> 305 | P15: =AQ6 -> 301 | Q15: =AO7 -> 89 | R15: =AP7 -> 89 | S15: =AQ7 -> 89 | T15: =AO8 -> 53 | U15: =AP8 -> 53 | V15: =AQ8 -> 53 | W15: =AO9 -> 364 | X15: =AP9 -> 364 | Y15: =AQ9 -> 364 | Z15: =AO10 -> 997 | AA15: =AP10 -> 997 | AB15: =AQ10 -> 997 | AC15: =AO11 -> 337 | AD15: =AP11 -> 322 | AE15: =AQ11 -> 309 | AF15: =AO12 -> 337 | AG15: =AP12 -> 321 | AH15: =AQ12 -> 309 | AI15: =AO13 -> 337 | AJ15: =AP13 -> 321 | AK15: =AQ13 -> 309 | AL15: =AO14 -> 337 | AM15: =AP14 -> 323 | AN15: =AQ14 -> 309 | AO15: 0 | AP15: 0 | AQ15: 0 | AR15: 289 | AS15: 289 | AT15: 289 | AU15: 63 | AV15: 63 | AW15: 63 | AX15: 734 | AY15: 734 | AZ15: 734 | BA15: 661 | BB15: 657 | BC15: 309 | BD15: 504 | BE15: 504 | BF15: 504 | BG15: 337 | BH15: 323 | BI15: 309 | BJ15: 337 | BK15: 322 | BL15: 309 | BM15: 601 | BN15: 518 | BO15: 482 | BP15: 540 | BQ15: 540 | BR15: 540 | BS15: 559 | BT15: 559 | BU15: 559 | BV15: 337 | BW15: 322 | BX15: 309 | BY15: 96 | BZ15: 96 | CA15: 96 | CB15: 778 | CC15: 778 | CD15: 778 | CE15: 312 | CF15: 310 | CG15: 308 | CH15: 337 | CI15: 322 | CJ15: 309 | CK15: 337 | CL15: 321 | CM15: 309 | CN15: 337 | CO15: 320 | CP15: 309 | CQ15: 266 | CR15: 266 | CS15: 266 | CT15: 337 | CU15: 321 | CV15: 309 | CW15: 337 | CX15: 322 | CY15: 309 | CZ15: 337 | DA15: 321 | DB15: 309 | DC15: 337 | DD15: 321 | DE15: 310 | DF15: 337 | DG15: 321 | DH15: 310 | DI15: 337 | DJ15: 321 | DK15: 309 | DL15: 337 | DM15: 322 | DN15: 309
A16: TEESPORT | B16: =AR2 -> 388 | C16: =AS2 -> 383 | D16: =AT2 -> 378 | E16: =AR3 -> 586 | F16: =AS3 -> 560 | G16: =AT3 -> 295 | H16: =AR4 -> 275 | I16: =AS4 -> 273 | J16: =AT4 -> 271 | K16: =AR5 -> 586 | L16: =AS5 -> 560 | M16: =AT5 -> 295 | N16: =AR6 -> 295 | O16: =AS6 -> 295 | P16: =AT6 -> 295 | Q16: =AR7 -> 314 | R16: =AS7 -> 314 | S16: =AT7 -> 314 | T16: =AR8 -> 283 | U16: =AS8 -> 283 | V16: =AT8 -> 283 | W16: =AR9 -> 413 | X16: =AS9 -> 413 | Y16: =AT9 -> 413 | Z16: =AR10 -> 1040 | AA16: =AS10 -> 1046 | AB16: =AT10 -> 1046 | AC16: =AR11 -> 586 | AD16: =AS11 -> 572 | AE16: =AT11 -> 559 | AF16: =AR12 -> 586 | AG16: =AS12 -> 559 | AH16: =AT12 -> 295 | AI16: =AR13 -> 586 | AJ16: =AS13 -> 559 | AK16: =AT13 -> 295 | AL16: =AR14 -> 586 | AM16: =AS14 -> 559 | AN16: =AT14 -> 295 | AO16: =AR15 -> 289 | AP16: =AS15 -> 289 | AQ16: =AT15 -> 289 | AR16: 0 | AS16: 0 | AT16: 0 | AU16: 288 | AV16: 288 | AW16: 288 | AX16: 783 | AY16: 783 | AZ16: 783 | BA16: 479 | BB16: 447 | BC16: 295 | BD16: 355 | BE16: 355 | BF16: 355 | BG16: 586 | BH16: 572 | BI16: 559 | BJ16: 586 | BK16: 571 | BL16: 559 | BM16: 359 | BN16: 359 | BO16: 359 | BP16: 589 | BQ16: 589 | BR16: 589 | BS16: 579 | BT16: 579 | BU16: 579 | BV16: 586 | BW16: 570 | BX16: 559 | BY16: 304 | BZ16: 304 | CA16: 304 | CB16: 827 | CC16: 827 | CD16: 827 | CE16: 561 | CF16: 559 | CG16: 557 | CH16: 586 | CI16: 571 | CJ16: 559 | CK16: 586 | CL16: 573 | CM16: 559 | CN16: 586 | CO16: 572 | CP16: 559 | CQ16: 327 | CR16: 327 | CS16: 327 | CT16: 586 | CU16: 571 | CV16: 559 | CW16: 586 | CX16: 571 | CY16: 559 | CZ16: 586 | DA16: 571 | DB16: 559 | DC16: 586 | DD16: 571 | DE16: 559 | DF16: 586 | DG16: 571 | DH16: 559 | DI16: 586 | DJ16: 572 | DK16: 559 | DL16: 586 | DM16: 570 | DN16: 559
A17: VLISSINGEN | B17: =AU2 -> 305 | C17: =AV2 -> 300 | D17: =AW2 -> 297 | E17: =AU3 -> 377 | F17: =AV3 -> 361 | G17: =AW3 -> 350 | H17: =AU4 -> 60 | I17: =AV4 -> 58 | J17: =AW4 -> 57 | K17: =AU5 -> 377 | L17: =AV5 -> 359 | M17: =AW5 -> 350 | N17: =AU6 -> 350 | O17: =AV6 -> 350 | P17: =AW6 -> 350 | Q17: =AU7 -> 26 | R17: =AV7 -> 26 | S17: =AW7 -> 26 | T17: =AU8 -> 17 | U17: =AV8 -> 17 | V17: =AW8 -> 17 | W17: =AU9 -> 334 | X17: =AV9 -> 334 | Y17: =AW9 -> 334 | Z17: =AU10 -> 967 | AA17: =AV10 -> 967 | AB17: =AW10 -> 967 | AC17: =AU11 -> 377 | AD17: =AV11 -> 362 | AE17: =AW11 -> 350 | AF17: =AU12 -> 377 | AG17: =AV12 -> 361 | AH17: =AW12 -> 350 | AI17: =AU13 -> 377 | AJ17: =AV13 -> 363 | AK17: =AW13 -> 350 | AL17: =AU14 -> 377 | AM17: =AV14 -> 364 | AN17: =AW14 -> 350 | AO17: =AU15 -> 63 | AP17: =AV15 -> 63 | AQ17: =AW15 -> 63 | AR17: =AU16 -> 288 | AS17: =AV16 -> 288 | AT17: =AW16 -> 288 | AU17: 0 | AV17: 0 | AW17: 0 | AX17: 704 | AY17: 704 | AZ17: 704 | BA17: 644 | BB17: 532 | BC17: 351 | BD17: 484 | BE17: 484 | BF17: 484 | BG17: 377 | BH17: 361 | BI17: 350 | BJ17: 377 | BK17: 360 | BL17: 350 | BM17: 499 | BN17: 499 | BO17: 499 | BP17: 510 | BQ17: 510 | BR17: 510 | BS17: 530 | BT17: 530 | BU17: 530 | BV17: 377 | BW17: 362 | BX17: 350 | BY17: 128 | BZ17: 128 | CA17: 128 | CB17: 749 | CC17: 749 | CD17: 749 | CE17: 358 | CF17: 355 | CG17: 350 | CH17: 377 | CI17: 361 | CJ17: 350 | CK17: 377 | CL17: 363 | CM17: 350 | CN17: 377 | CO17: 362 | CP17: 350 | CQ17: 236 | CR17: 236 | CS17: 236 | CT17: 377 | CU17: 362 | CV17: 350 | CW17: 377 | CX17: 362 | CY17: 350 | CZ17: 377 | DA17: 361 | DB17: 350 | DC17: 337 | DD17: 360 | DE17: 350 | DF17: 377 | DG17: 362 | DH17: 350 | DI17: 377 | DJ17: 361 | DK17: 350 | DL17: 377 | DM17: 361 | DN17: 350
A18: GDANSK | B18: =AX2 -> 495 | C18: =AY2 -> 490 | D18: =AZ2 -> 487 | E18: =AX3 -> 1043 | F18: =AY3 -> 1017 | G18: =AZ3 -> 901 | H18: =AX4 -> 660 | I18: =AY4 -> 658 | J18: =AZ4 -> 656 | K18: =AX5 -> 1043 | L18: =AY5 -> 1016 | M18: =AZ5 -> 902 | N18: =AX6 -> 1016 | O18: =AY6 -> 901 | P18: =AZ6 -> 832 | Q18: =AX7 -> 729 | R18: =AY7 -> 729 | S18: =AZ7 -> 729 | T18: =AX8 -> 702 | U18: =AY8 -> 702 | V18: =AZ8 -> 702 | W18: =AX9 -> 438 | X18: =AY9 -> 438 | Y18: =AZ9 -> 438 | Z18: =AX10 -> 414 | AA18: =AY10 -> 414 | AB18: =AZ10 -> 414 | AC18: ='Distance outside the ECA'!AW11 -> 1016 | AD18: =AY11 -> 1029 | AE18: =AZ11 -> 1016 | AF18: =AX12 -> 1043 | AG18: =AY12 -> 1029 | AH18: =AZ12 -> 1016 | AI18: =AX13 -> 1263 | AJ18: =AY13 -> 1236 | AK18: =AZ13 -> 901 | AL18: =AX14 -> 1255 | AM18: =AY14 -> 1229 | AN18: =AZ14 -> 901 | AO18: =AX15 -> 734 | AP18: =AY15 -> 734 | AQ18: =AZ15 -> 734 | AR18: =AX16 -> 783 | AS18: =AY16 -> 783 | AT18: =AZ16 -> 783 | AU18: =AX17 -> 704 | AV18: =AY17 -> 704 | AW18: =AZ17 -> 704 | AX18: 0 | AY18: 0 | AZ18: 0 | BA18: 833 | BB18: 833 | BC18: 833 | BD18: 668 | BE18: 668 | BF18: 668 | BG18: 1043 | BH18: 1029 | BI18: 1016 | BJ18: 1043 | BK18: 1029 | BL18: 1016 | BM18: 686 | BN18: 686 | BO18: 686 | BP18: 281 | BQ18: 281 | BR18: 281 | BS18: 302 | BT18: 302 | BU18: 302 | BV18: 1043 | BW18: 1027 | BX18: 1016 | BY18: 771 | BZ18: 771 | CA18: 771 | CB18: 119 | CC18: 119 | CD18: 119 | CE18: 1024 | CF18: 1018 | CG18: 1016 | CH18: 1043 | CI18: 1028 | CJ18: 1016 | CK18: 1043 | CL18: 1029 | CM18: 1016 | CN18: 1043 | CO18: 1028 | CP18: 1016 | CQ18: 534 | CR18: 534 | CS18: 534 | CT18: 1043 | CU18: 1027 | CV18: 1016 | CW18: 1043 | CX18: 1027 | CY18: 1016 | CZ18: 1043 | DA18: 1029 | DB18: 1016 | DC18: 1043 | DD18: 1032 | DE18: 1017 | DF18: 1039 | DG18: 1027 | DH18: 1017 | DI18: 1040 | DJ18: 1025 | DK18: 1017 | DL18: 1038 | DM18: 1030 | DN18: 1020
A19: MO I RANA | B19: =BB2 -> 543 | C19: =BA2 -> 576 | D19: =BC2 -> 536 | E19: =BA3 -> 961 | F19: =BB3 -> 936 | G19: =BC3 -> 0 | H19: =BA4 -> 605 | I19: =BB4 -> 603 | J19: =BC4 -> 378 | K19: =BA5 -> 205 | L19: =BB5 -> 90 | M19: =BC5 -> 0 | N19: =BA6 -> 205 | O19: =BB6 -> 125 | P19: =BC6 -> 0 | Q19: =BA7 -> 670 | R19: =BB7 -> 669 | S19: =BC7 -> 375 | T19: =BA8 -> 642 | U19: =BB8 -> 640 | V19: =BC8 -> 339 | W19: =BA9 -> 649 | X19: =BB9 -> 562 | Y19: =BC9 -> 378 | Z19: =BA10 -> 1085 | AA19: =BB10 -> 1085 | AB19: =BC10 -> 1085 | AC19: =BA11 -> 933 | AD19: =BB11 -> 205 | AE19: =BC11 -> 0 | AF19: =BA12 -> 205 | AG19: =BB12 -> 108 | AH19: =BC12 -> 0 | AI19: =BA13 -> 933 | AJ19: =BB13 -> 240 | AK19: =BC13 -> 0 | AL19: =BA14 -> 934 | AM19: =BB14 -> 307 | AN19: =BC14 -> 0 | AO19: =BA15 -> 661 | AP19: =BB15 -> 657 | AQ19: =BC15 -> 309 | AR19: =BA16 -> 479 | AS19: =BB16 -> 447 | AT19: =BC16 -> 295 | AU19: =BA17 -> 644 | AV19: =BB17 -> 532 | AW19: =BC17 -> 351 | AX19: =BA18 -> 833 | AY19: =BB18 -> 833 | AZ19: =BC18 -> 833 | BA19: 0 | BB19: 0 | BC19: 0 | BD19: 210 | BE19: 210 | BF19: 210 | BG19: 205 | BH19: 102 | BI19: 0 | BJ19: 205 | BK19: 96 | BL19: 0 | BM19: 173 | BN19: 173 | BO19: 173 | BP19: 562 | BQ19: 562 | BR19: 562 | BS19: 533 | BT19: 533 | BU19: 533 | BV19: 205 | BW19: 114 | BX19: 0 | BY19: 678 | BZ19: 675 | CA19: 351 | CB19: 868 | CC19: 868 | CD19: 868 | CE19: 936 | CF19: 231 | CG19: 23 | CH19: 205 | CI19: 105 | CJ19: 0 | CK19: 961 | CL19: 218 | CM19: 0 | CN19: 205 | CO19: 118 | CP19: 0 | CQ19: 542 | CR19: 542 | CS19: 542 | CT19: 195 | CU19: 109 | CV19: 0 | CW19: 961 | CX19: 301 | CY19: 0 | CZ19: 205 | DA19: 100 | DB19: 0 | DC19: 964 | DD19: 300 | DE19: 0 | DF19: 965 | DG19: 306 | DH19: 0 | DI19: 955 | DJ19: 288 | DK19: 0 | DL19: 966 | DM19: 309 | DN19: 0
A20: STAVANGER | B20: =BD2 -> 385 | C20: =BE2 -> 382 | D20: =BF2 -> 379 | E20: =BD3 -> 805 | F20: =BE3 -> 779 | G20: =BF3 -> 210 | H20: =BD4 -> 445 | I20: =BE4 -> 443 | J20: =BF4 -> 442 | K20: =BD5 -> 805 | L20: =BE5 -> 308 | M20: =BF5 -> 210 | N20: =BD6 -> 311 | O20: =BE6 -> 307 | P20: =BF6 -> 210 | Q20: =BD7 -> 510 | R20: =BE7 -> 510 | S20: =BF7 -> 510 | T20: =BD8 -> 483 | U20: =BE8 -> 483 | V20: =BF8 -> 483 | W20: =BD9 -> 398 | X20: =BE9 -> 398 | Y20: =BF9 -> 398 | Z20: =BD10 -> 921 | AA20: =BE10 -> 921 | AB20: =BF10 -> 921 | AC20: =BD11 -> 805 | AD20: =BE11 -> 778 | AE20: =BF11 -> 210 | AF20: =BD12 -> 805 | AG20: =BE12 -> 778 | AH20: =BF12 -> 210 | AI20: =BD13 -> 778 | AJ20: =BE13 -> 307 | AK20: =BF13 -> 210 | AL20: =BD14 -> 805 | AM20: =BE14 -> 307 | AN20: =BF14 -> 210 | AO20: =BD15 -> 504 | AP20: =BE15 -> 504 | AQ20: =BF15 -> 504 | AR20: =BD16 -> 355 | AS20: =BE16 -> 355 | AT20: =BF16 -> 355 | AU20: =BD17 -> 484 | AV20: =BE17 -> 484 | AW20: =BF17 -> 484 | AX20: =BD18 -> 668 | AY20: =BE18 -> 668 | AZ20: =BF18 -> 668 | BA20: =BD19 -> 210 | BB20: =BE19 -> 210 | BC20: =BF19 -> 210 | BD20: 0 | BE20: 0 | BF20: 0 | BG20: 805 | BH20: 307 | BI20: 210 | BJ20: 805 | BK20: 308 | BL20: 210 | BM20: 63 | BN20: 63 | BO20: 63 | BP20: 398 | BQ20: 398 | BR20: 398 | BS20: 369 | BT20: 369 | BU20: 369 | BV20: 794 | BW20: 310 | BX20: 210 | BY20: 523 | BZ20: 523 | CA20: 523 | CB20: 704 | CC20: 704 | CD20: 704 | CE20: 780 | CF20: 333 | CG20: 233 | CH20: 814 | CI20: 308 | CJ20: 210 | CK20: 783 | CL20: 307 | CM20: 210 | CN20: 788 | CO20: 310 | CP20: 210 | CQ20: 378 | CR20: 378 | CS20: 378 | CT20: 790 | CU20: 304 | CV20: 210 | CW20: 786 | CX20: 306 | CY20: 210 | CZ20: 782 | DA20: 306 | DB20: 210 | DC20: 778 | DD20: 307 | DE20: 210 | DF20: 780 | DG20: 304 | DH20: 210 | DI20: 784 | DJ20: 308 | DK20: 210 | DL20: 782 | DM20: 308 | DN20: 210
A21: LISBON | B21: =BG2 -> 637 | C21: =BH2 -> 609 | D21: =BI2 -> 536 | E21: =BG3 -> 0 | F21: =BH3 -> 0 | G21: =BI3 -> 0 | H21: =BG4 -> 405 | I21: =BH4 -> 387 | J21: =BI4 -> 378 | K21: =BG5 -> 0 | L21: =BH5 -> 0 | M21: =BI5 -> 0 | N21: =BG6 -> 0 | O21: =BH6 -> 0 | P21: =BI6 -> 0 | Q21: =BG7 -> 403 | R21: =BH7 -> 385 | S21: =BI7 -> 375 | T21: =BG8 -> 367 | U21: =BH8 -> 350 | V21: =BI8 -> 339 | W21: =BG9 -> 674 | X21: =BH9 -> 657 | Y21: =BI9 -> 646 | Z21: =BG10 -> 1307 | AA21: =BH10 -> 1290 | AB21: =BI10 -> 1279 | AC21: =BG11 -> 0 | AD21: =BH11 -> 0 | AE21: =BI11 -> 0 | AF21: =BG12 -> 0 | AG21: =BH12 -> 0 | AH21: =BI12 -> 0 | AI21: =BG13 -> 0 | AJ21: =BH13 -> 0 | AK21: =BI13 -> 0 | AL21: =BG14 -> 0 | AM21: =BH14 -> 0 | AN21: =BI14 -> 0 | AO21: =BG15 -> 337 | AP21: =BH15 -> 323 | AQ21: =BI15 -> 309 | AR21: =BG16 -> 586 | AS21: =BH16 -> 572 | AT21: =BI16 -> 559 | AU21: =BG17 -> 377 | AV21: =BH17 -> 361 | AW21: =BI17 -> 350 | AX21: =BG18 -> 1043 | AY21: =BH18 -> 1029 | AZ21: =BI18 -> 1016 | BA21: =BG19 -> 205 | BB21: =BH19 -> 102 | BC21: =BI19 -> 0 | BD21: =BG20 -> 805 | BE21: =BH20 -> 307 | BF21: =BI20 -> 210 | BG21: 0 | BH21: 0 | BI21: 0 | BJ21: 0 | BK21: 0 | BL21: 0 | BM21: 805 | BN21: 291 | BO21: 173 | BP21: 849 | BQ21: 835 | BR21: 822 | BS21: 869 | BT21: 854 | BU21: 842 | BV21: 0 | BW21: 0 | BX21: 0 | BY21: 379 | BZ21: 367 | CA21: 352 | CB21: 1088 | CC21: 1072 | CD21: 1062 | CE21: 28 | CF21: 16 | CG21: 0 | CH21: 0 | CI21: 0 | CJ21: 0 | CK21: 0 | CL21: 0 | CM21: 0 | CN21: 0 | CO21: 0 | CP21: 0 | CQ21: 575 | CR21: 561 | CS21: 549 | CT21: 0 | CU21: 0 | CV21: 0 | CW21: 0 | CX21: 0 | CY21: 0 | CZ21: 0 | DA21: 0 | DB21: 0 | DC21: 0 | DD21: 0 | DE21: 0 | DF21: 0 | DG21: 0 | DH21: 0 | DI21: 0 | DJ21: 0 | DK21: 0 | DL21: 0 | DM21: 0 | DN21: 0
A22: SETUBAL | B22: =BJ2 -> 637 | C22: =BK2 -> 609 | D22: =BL2 -> 536 | E22: =BJ3 -> 0 | F22: =BK3 -> 0 | G22: =BL3 -> 0 | H22: =BJ4 -> 405 | I22: =BK4 -> 387 | J22: =BL4 -> 378 | K22: =BJ5 -> 0 | L22: =BK5 -> 0 | M22: =BL5 -> 0 | N22: =BJ6 -> 0 | O22: =BK6 -> 0 | P22: =BL6 -> 0 | Q22: =BJ7 -> 403 | R22: =BK7 -> 388 | S22: =BL7 -> 375 | T22: =BJ8 -> 367 | U22: =BK8 -> 351 | V22: =BL8 -> 339 | W22: =BJ9 -> 674 | X22: =BK9 -> 658 | Y22: =BL9 -> 646 | Z22: =BJ10 -> 1307 | AA22: =BK10 -> 1292 | AB22: =BL10 -> 1279 | AC22: =BJ11 -> 0 | AD22: =BK11 -> 0 | AE22: =BL11 -> 0 | AF22: =BJ12 -> 0 | AG22: =BK12 -> 0 | AH22: =BL12 -> 0 | AI22: =BJ13 -> 0 | AJ22: =BK13 -> 0 | AK22: =BL13 -> 0 | AL22: =BJ14 -> 0 | AM22: =BK14 -> 0 | AN22: =BL14 -> 0 | AO22: =BJ15 -> 337 | AP22: =BK15 -> 322 | AQ22: =BL15 -> 309 | AR22: =BJ16 -> 586 | AS22: =BK16 -> 571 | AT22: =BL16 -> 559 | AU22: =BJ17 -> 377 | AV22: =BK17 -> 360 | AW22: =BL17 -> 350 | AX22: =BJ18 -> 1043 | AY22: =BK18 -> 1029 | AZ22: =BL18 -> 1016 | BA22: =BJ19 -> 205 | BB22: =BK19 -> 96 | BC22: =BL19 -> 0 | BD22: =BJ20 -> 805 | BE22: =BK20 -> 308 | BF22: =BL20 -> 210 | BG22: =BJ21 -> 0 | BH22: =BK21 -> 0 | BI22: =BL21 -> 0 | BJ22: 0 | BK22: 0 | BL22: 0 | BM22: 818 | BN22: 291 | BO22: 173 | BP22: 827 | BQ22: 631 | BR22: 569 | BS22: 844 | BT22: 602 | BU22: 533 | BV22: 0 | BW22: 0 | BX22: 0 | BY22: 379 | BZ22: 362 | CA22: 352 | CB22: 1073 | CC22: 937 | CD22: 868 | CE22: 23 | CF22: 12 | CG22: 0 | CH22: 0 | CI22: 0 | CJ22: 0 | CK22: 0 | CL22: 0 | CM22: 0 | CN22: 0 | CO22: 0 | CP22: 0 | CQ22: 575 | CR22: 548 | CS22: 505 | CT22: 0 | CU22: 0 | CV22: 0 | CW22: 0 | CX22: 0 | CY22: 0 | CZ22: 0 | DA22: 0 | DB22: 0 | DC22: 0 | DD22: 0 | DE22: 0 | DF22: 0 | DG22: 0 | DH22: 0 | DI22: 0 | DJ22: 0 | DK22: 0 | DL22: 0 | DM22: 0 | DN22: 0
A23: ORESUND | B23: =BM2 -> 405 | C23: =BN2 -> 400 | D23: =BO2 -> 396 | E23: =BM3 -> 818 | F23: =BN3 -> 791 | G23: =BO3 -> 173 | H23: =BM4 -> 460 | I23: =BN4 -> 458 | J23: =BO4 -> 457 | K23: =BM5 -> 818 | L23: =BN5 -> 284 | M23: =BO5 -> 173 | N23: =BM6 -> 0 | O23: =BN6 -> 0 | P23: =BO6 -> 0 | Q23: =BM7 -> 525 | R23: =BN7 -> 525 | S23: =BO7 -> 525 | T23: =BM8 -> 497 | U23: =BN8 -> 497 | V23: =BO8 -> 497 | W23: =BM9 -> 415 | X23: =BN9 -> 415 | Y23: =BO9 -> 415 | Z23: =BM10 -> 938 | AA23: =BN10 -> 938 | AB23: =BO10 -> 938 | AC23: =BM11 -> 818 | AD23: =BN11 -> 791 | AE23: =BO11 -> 173 | AF23: =BM12 -> 818 | AG23: =BN12 -> 791 | AH23: =BO12 -> 173 | AI23: =BM13 -> 791 | AJ23: =BN13 -> 291 | AK23: =BO13 -> 173 | AL23: =BM14 -> 799 | AM23: =BN14 -> 292 | AN23: =BO14 -> 173 | AO23: =BM15 -> 601 | AP23: =BN15 -> 518 | AQ23: =BO15 -> 482 | AR23: =BM16 -> 359 | AS23: =BN16 -> 359 | AT23: =BO16 -> 359 | AU23: =BM17 -> 499 | AV23: =BN17 -> 499 | AW23: =BO17 -> 499 | AX23: =BM18 -> 686 | AY23: =BN18 -> 686 | AZ23: =BO18 -> 686 | BA23: =BM19 -> 173 | BB23: =BN19 -> 173 | BC23: =BO19 -> 173 | BD23: =BM20 -> 63 | BE23: =BN20 -> 63 | BF23: =BO20 -> 63 | BG23: =BM21 -> 805 | BH23: =BN21 -> 291 | BI23: =BO21 -> 173 | BJ23: =BM22 -> 818 | BK23: =BN22 -> 291 | BL23: =BO22 -> 173 | BM23: 0 | BN23: 0 | BO23: 0 | BP23: 415 | BQ23: 415 | BR23: 415 | BS23: 386 | BT23: 386 | BU23: 386 | BV23: 802 | BW23: 292 | BX23: 173 | BY23: 536 | BZ23: 536 | CA23: 536 | CB23: 722 | CC23: 722 | CD23: 722 | CE23: 797 | CF23: 315 | CG23: 196 | CH23: 818 | CI23: 292 | CJ23: 173 | CK23: 818 | CL23: 292 | CM23: 173 | CN23: 818 | CO23: 287 | CP23: 173 | CQ23: 395 | CR23: 395 | CS23: 395 | CT23: 799 | CU23: 292 | CV23: 173 | CW23: 806 | CX23: 284 | CY23: 173 | CZ23: 818 | DA23: 284 | DB23: 173 | DC23: 807 | DD23: 294 | DE23: 173 | DF23: 803 | DG23: 284 | DH23: 173 | DI23: 792 | DJ23: 284 | DK23: 173 | DL23: 797 | DM23: 295 | DN23: 173
A24: MALMO | B24: =BP2 -> 305 | C24: =BQ2 -> 300 | D24: =BR2 -> 293 | E24: =BP3 -> 849 | F24: =BQ3 -> 822 | G24: =BR3 -> 562 | H24: =BP4 -> 465 | I24: =BQ4 -> 463 | J24: =BR4 -> 462 | K24: =BP5 -> 849 | L24: =BQ5 -> 631 | M24: =BR5 -> 562 | N24: =BP6 -> 822 | O24: =BQ6 -> 631 | P24: =BR6 -> 562 | Q24: =BP7 -> 535 | R24: =BQ7 -> 535 | S24: =BR7 -> 535 | T24: =BP8 -> 509 | U24: =BQ8 -> 509 | V24: =BR8 -> 509 | W24: =BP9 -> 244 | X24: =BQ9 -> 244 | Y24: =BR9 -> 244 | Z24: =BP10 -> 533 | AA24: =BQ10 -> 533 | AB24: =BR10 -> 533 | AC24: =BP11 -> 849 | AD24: =BQ11 -> 822 | AE24: =BR11 -> 562 | AF24: =BP12 -> 849 | AG24: =BQ12 -> 822 | AH24: =BR12 -> 562 | AI24: =BP13 -> 822 | AJ24: =BQ13 -> 631 | AK24: =BR13 -> 562 | AL24: =BP14 -> 984 | AM24: =BQ14 -> 631 | AN24: =BR14 -> 562 | AO24: =BP15 -> 540 | AP24: =BQ15 -> 540 | AQ24: =BR15 -> 540 | AR24: =BP16 -> 589 | AS24: =BQ16 -> 589 | AT24: =BR16 -> 589 | AU24: =BP17 -> 510 | AV24: =BQ17 -> 510 | AW24: =BR17 -> 510 | AX24: =BP18 -> 281 | AY24: =BQ18 -> 281 | AZ24: =BR18 -> 281 | BA24: =BP19 -> 562 | BB24: =BQ19 -> 562 | BC24: =BR19 -> 562 | BD24: =BP20 -> 398 | BE24: =BQ20 -> 398 | BF24: =BR20 -> 398 | BG24: =BP21 -> 849 | BH24: =BQ21 -> 835 | BI24: =BR21 -> 822 | BJ24: =BP22 -> 827 | BK24: =BQ22 -> 631 | BL24: =BR22 -> 569 | BM24: =BP23 -> 415 | BN24: =BQ23 -> 415 | BO24: =BR23 -> 415 | BP24: 0 | BQ24: 0 | BR24: 0 | BS24: 32 | BT24: 32 | BU24: 32 | BV24: 849 | BW24: 635 | BX24: 562 | BY24: 577 | BZ24: 577 | CA24: 577 | CB24: 317 | CC24: 317 | CD24: 317 | CE24: 824 | CF24: 659 | CG24: 585 | CH24: 849 | CI24: 631 | CJ24: 562 | CK24: 837 | CL24: 632 | CM24: 562 | CN24: 835 | CO24: 631 | CP24: 562 | CQ24: 340 | CR24: 340 | CS24: 340 | CT24: 835 | CU24: 633 | CV24: 562 | CW24: 839 | CX24: 631 | CY24: 562 | CZ24: 840 | DA24: 631 | DB24: 562 | DC24: 841 | DD24: 631 | DE24: 562 | DF24: 822 | DG24: 631 | DH24: 562 | DI24: 849 | DJ24: 631 | DK24: 562 | DL24: 876 | DM24: 634 | DN24: 562
A25: HELSINGBORG | B25: =BS2 -> 320 | C25: =BT2 -> 315 | D25: =BU2 -> 313 | E25: =BS3 -> 871 | F25: =BT3 -> 843 | G25: =BU3 -> 533 | H25: =BS4 -> 485 | I25: =BT4 -> 483 | J25: =BU4 -> 482 | K25: =BS5 -> 869 | L25: =BT5 -> 602 | M25: =BU5 -> 533 | N25: =BS6 -> 608 | O25: =BT6 -> 602 | P25: =BU6 -> 533 | Q25: =BS7 -> 555 | R25: =BT7 -> 555 | S25: =BU7 -> 555 | T25: =BS8 -> 528 | U25: =BT8 -> 528 | V25: =BU8 -> 528 | W25: =BS9 -> 264 | X25: =BT9 -> 264 | Y25: =BU9 -> 264 | Z25: =BS10 -> 555 | AA25: =BT10 -> 555 | AB25: =BU10 -> 555 | AC25: =BS11 -> 869 | AD25: =BT11 -> 842 | AE25: =BU11 -> 533 | AF25: =BS12 -> 871 | AG25: =BT12 -> 842 | AH25: =BU12 -> 533 | AI25: =BS13 -> 842 | AJ25: =BT13 -> 602 | AK25: =BU13 -> 533 | AL25: =BS14 -> 955 | AM25: =BT14 -> 602 | AN25: =BU14 -> 533 | AO25: =BS15 -> 559 | AP25: =BT15 -> 559 | AQ25: =BU15 -> 559 | AR25: =BS16 -> 579 | AS25: =BT16 -> 579 | AT25: =BU16 -> 579 | AU25: =BS17 -> 530 | AV25: =BT17 -> 530 | AW25: =BU17 -> 530 | AX25: =BS18 -> 302 | AY25: =BT18 -> 302 | AZ25: =BU18 -> 302 | BA25: =BS19 -> 533 | BB25: =BT19 -> 533 | BC25: =BU19 -> 533 | BD25: =BS20 -> 369 | BE25: =BT20 -> 369 | BF25: =BU20 -> 369 | BG25: =BS21 -> 869 | BH25: =BT21 -> 854 | BI25: =BU21 -> 842 | BJ25: =BS22 -> 844 | BK25: =BT22 -> 602 | BL25: =BU22 -> 533 | BM25: =BS23 -> 386 | BN25: =BT23 -> 386 | BO25: =BU23 -> 386 | BP25: =BS24 -> 32 | BQ25: =BT24 -> 32 | BR25: =BU24 -> 32 | BS25: 0 | BT25: 0 | BU25: 0 | BV25: 869 | BW25: 602 | BX25: 533 | BY25: 597 | BZ25: 597 | CA25: 597 | CB25: 338 | CC25: 338 | CD25: 338 | CE25: 848 | CF25: 843 | CG25: 844 | CH25: 844 | CI25: 602 | CJ25: 533 | CK25: 855 | CL25: 602 | CM25: 533 | CN25: 858 | CO25: 602 | CP25: 543 | CQ25: 360 | CR25: 360 | CS25: 360 | CT25: 856 | CU25: 605 | CV25: 533 | CW25: 869 | CX25: 855 | CY25: 842 | CZ25: 869 | DA25: 854 | DB25: 842 | DC25: 869 | DD25: 855 | DE25: 842 | DF25: 869 | DG25: 854 | DH25: 842 | DI25: 869 | DJ25: 852 | DK25: 842 | DL25: 869 | DM25: 854 | DN25: 842
A26: SINES | B26: =BV2 -> 637 | C26: =BW2 -> 609 | D26: =BX2 -> 536 | E26: =BV3 -> 0 | F26: =BW3 -> 0 | G26: =BX3 -> 0 | H26: =BV4 -> 405 | I26: =BW4 -> 389 | J26: =BX4 -> 378 | K26: =BV5 -> 0 | L26: =BW5 -> 0 | M26: =BX5 -> 0 | N26: =BV6 -> 0 | O26: =BW6 -> 0 | P26: =BX6 -> 0 | Q26: =BV7 -> 403 | R26: =BW7 -> 385 | S26: =BX7 -> 375 | T26: =BV8 -> 367 | U26: =BW8 -> 351 | V26: =BX8 -> 339 | W26: =BV9 -> 674 | X26: =BW9 -> 657 | Y26: =BX9 -> 646 | Z26: =BV10 -> 1307 | AA26: =BW10 -> 1290 | AB26: =BX10 -> 1279 | AC26: =BV11 -> 0 | AD26: =BW11 -> 0 | AE26: =BX11 -> 0 | AF26: =BV12 -> 0 | AG26: =BW12 -> 0 | AH26: =BX12 -> 0 | AI26: =BV13 -> 0 | AJ26: =BW13 -> 0 | AK26: =BX13 -> 0 | AL26: =BV14 -> 0 | AM26: =BW14 -> 0 | AN26: =BX14 -> 0 | AO26: =BV15 -> 337 | AP26: =BW15 -> 322 | AQ26: =BX15 -> 309 | AR26: =BV16 -> 586 | AS26: =BW16 -> 570 | AT26: =BX16 -> 559 | AU26: =BV17 -> 377 | AV26: =BW17 -> 362 | AW26: =BX17 -> 350 | AX26: =BV18 -> 1043 | AY26: =BW18 -> 1027 | AZ26: =BX18 -> 1016 | BA26: =BV19 -> 205 | BB26: =BW19 -> 114 | BC26: =BX19 -> 0 | BD26: =BV20 -> 794 | BE26: =BW20 -> 310 | BF26: =BX20 -> 210 | BG26: =BV21 -> 0 | BH26: =BW21 -> 0 | BI26: =BX21 -> 0 | BJ26: =BV22 -> 0 | BK26: =BW22 -> 0 | BL26: =BX22 -> 0 | BM26: =BV23 -> 802 | BN26: =BW23 -> 292 | BO26: =BX23 -> 173 | BP26: =BV24 -> 849 | BQ26: =BW24 -> 635 | BR26: =BX24 -> 562 | BS26: =BV25 -> 869 | BT26: =BW25 -> 602 | BU26: =BX25 -> 533 | BV26: 0 | BW26: 0 | BX26: 0 | BY26: 379 | BZ26: 365 | CA26: 352 | CB26: 1088 | CC26: 1075 | CD26: 1061 | CE26: 28 | CF26: 14 | CG26: 0 | CH26: 0 | CI26: 0 | CJ26: 0 | CK26: 0 | CL26: 0 | CM26: 0 | CN26: 0 | CO26: 0 | CP26: 0 | CQ26: 575 | CR26: 566 | CS26: 552 | CT26: 0 | CU26: 0 | CV26: 0 | CW26: 0 | CX26: 0 | CY26: 0 | CZ26: 0 | DA26: 0 | DB26: 0 | DC26: 0 | DD26: 0 | DE26: 0 | DF26: 0 | DG26: 0 | DH26: 0 | DI26: 0 | DJ26: 0 | DK26: 0 | DL26: 0 | DM26: 0 | DN26: 0
A27: TILBURY | B27: =BY2 -> 370 | C27: =BZ2 -> 366 | D27: =CA2 -> 364 | E27: =BY3 -> 379 | F27: =BZ3 -> 361 | G27: =CA3 -> 352 | H27: =BY4 -> 150 | I27: =BZ4 -> 148 | J27: =CA4 -> 145 | K27: =BY5 -> 379 | L27: =BZ5 -> 362 | M27: =CA5 -> 351 | N27: =BY6 -> 356 | O27: =BZ6 -> 355 | P27: =CA6 -> 351 | Q27: =BY7 -> 153 | R27: =BZ7 -> 153 | S27: =CA7 -> 153 | T27: =BY8 -> 118 | U27: =BZ8 -> 118 | V27: =CA8 -> 118 | W27: =BY9 -> 401 | X27: =BZ9 -> 401 | Y27: =CA9 -> 401 | Z27: =BY10 -> 1046 | AA27: =BZ10 -> 1046 | AB27: =CA10 -> 1046 | AC27: =BY11 -> 379 | AD27: =BZ11 -> 363 | AE27: =CA11 -> 351 | AF27: =BY12 -> 379 | AG27: =BZ12 -> 363 | AH27: =CA12 -> 351 | AI27: =BY13 -> 379 | AJ27: =BZ13 -> 363 | AK27: =CA13 -> 352 | AL27: =BY14 -> 379 | AM27: =BZ14 -> 364 | AN27: =CA14 -> 352 | AO27: =BY15 -> 96 | AP27: =BZ15 -> 96 | AQ27: =CA15 -> 96 | AR27: =BY16 -> 304 | AS27: =BZ16 -> 304 | AT27: =CA16 -> 304 | AU27: =BY17 -> 128 | AV27: =BZ17 -> 128 | AW27: =CA17 -> 128 | AX27: =BY18 -> 771 | AY27: =BZ18 -> 771 | AZ27: =CA18 -> 771 | BA27: =BY19 -> 678 | BB27: =BZ19 -> 675 | BC27: =CA19 -> 351 | BD27: =BY20 -> 523 | BE27: =BZ20 -> 523 | BF27: =CA20 -> 523 | BG27: =BY21 -> 379 | BH27: =BZ21 -> 367 | BI27: =CA21 -> 352 | BJ27: =BY22 -> 379 | BK27: =BZ22 -> 362 | BL27: =CA22 -> 352 | BM27: =BY23 -> 536 | BN27: =BZ23 -> 536 | BO27: =CA23 -> 536 | BP27: =BY24 -> 577 | BQ27: =BZ24 -> 577 | BR27: =CA24 -> 577 | BS27: =BY25 -> 597 | BT27: =BZ25 -> 597 | BU27: =CA25 -> 597 | BV27: =BY26 -> 379 | BW27: =BZ26 -> 365 | BX27: =CA26 -> 352 | BY27: 0 | BZ27: 0 | CA27: 0 | CB27: 816 | CC27: 816 | CD27: 816 | CE27: 357 | CF27: 354 | CG27: 352 | CH27: 379 | CI27: 364 | CJ27: 352 | CK27: 376 | CL27: 365 | CM27: 367 | CN27: 378 | CO27: 368 | CP27: 353 | CQ27: 303 | CR27: 303 | CS27: 303 | CT27: 376 | CU27: 364 | CV27: 354 | CW27: 374 | CX27: 360 | CY27: 353 | CZ27: 377 | DA27: 371 | DB27: 354 | DC27: 377 | DD27: 366 | DE27: 355 | DF27: 375 | DG27: 365 | DH27: 356 | DI27: 379 | DJ27: 366 | DK27: 354 | DL27: 378 | DM27: 363 | DN27: 354
A28: KLAIPEDA | B28: =CB2 -> 540 | C28: =CC2 -> 536 | D28: =CD2 -> 532 | E28: =CB3 -> 1088 | F28: =CC3 -> 950 | G28: =CD3 -> 868 | H28: =CB4 -> 705 | I28: =CC4 -> 702 | J28: =CD4 -> 701 | K28: =CB5 -> 1088 | L28: =CC5 -> 1061 | M28: =CD5 -> 868 | N28: =CB6 -> 1061 | O28: =CC6 -> 937 | P28: =CD6 -> 868 | Q28: =CB7 -> 774 | R28: =CC7 -> 774 | S28: =CD7 -> 774 | T28: =CB8 -> 747 | U28: =CC8 -> 747 | V28: =CD8 -> 747 | W28: =CB9 -> 483 | X28: =CC9 -> 483 | Y28: =CD9 -> 483 | Z28: =CB10 -> 337 | AA28: =CC10 -> 337 | AB28: =CD10 -> 337 | AC28: =CB11 -> 1088 | AD28: =CC11 -> 1061 | AE28: =CD11 -> 868 | AF28: =CB12 -> 1088 | AG28: =CC12 -> 1061 | AH28: =CD12 -> 868 | AI28: =CB13 -> 1264 | AJ28: =CC13 -> 937 | AK28: =CD13 -> 868 | AL28: =CB14 -> 1290 | AM28: =CC14 -> 937 | AN28: =CD14 -> 868 | AO28: =CB15 -> 778 | AP28: =CC15 -> 778 | AQ28: =CD15 -> 778 | AR28: =CB16 -> 827 | AS28: =CC16 -> 827 | AT28: =CD16 -> 827 | AU28: =CB17 -> 749 | AV28: =CC17 -> 749 | AW28: =CD17 -> 749 | AX28: =CB18 -> 119 | AY28: =CC18 -> 119 | AZ28: =CD18 -> 119 | BA28: =CB19 -> 868 | BB28: =CC19 -> 868 | BC28: =CD19 -> 868 | BD28: =CB20 -> 704 | BE28: =CC20 -> 704 | BF28: =CD20 -> 704 | BG28: =CB21 -> 1088 | BH28: =CC21 -> 1072 | BI28: =CD21 -> 1062 | BJ28: =CB22 -> 1073 | BK28: =CC22 -> 937 | BL28: =CD22 -> 868 | BM28: =CB23 -> 722 | BN28: =CC23 -> 722 | BO28: =CD23 -> 722 | BP28: =CB24 -> 317 | BQ28: =CC24 -> 317 | BR28: =CD24 -> 317 | BS28: =CB25 -> 338 | BT28: =CC25 -> 338 | BU28: =CD25 -> 338 | BV28: =CB26 -> 1088 | BW28: =CC26 -> 1075 | BX28: =CD26 -> 1061 | BY28: =CB27 -> 816 | BZ28: =CC27 -> 816 | CA28: =CD27 -> 816 | CB28: 0 | CC28: 0 | CD28: 0 | CE28: 1061 | CF28: 1065 | CG28: 1062 | CH28: 1088 | CI28: 1073 | CJ28: 1063 | CK28: 1083 | CL28: 1072 | CM28: 1063 | CN28: 1085 | CO28: 1072 | CP28: 1061 | CQ28: 579 | CR28: 579 | CS28: 579 | CT28: 1088 | CU28: 1072 | CV28: 1061 | CW28: 1085 | CX28: 1073 | CY28: 1061 | CZ28: 1083 | DA28: 1074 | DB28: 1062 | DC28: 1084 | DD28: 1073 | DE28: 1061 | DF28: 1083 | DG28: 1073 | DH28: 1061 | DI28: 1086 | DJ28: 1076 | DK28: 1061 | DL28: 1084 | DM28: 1073 | DN28: 1061
A29: FALMOUTH | B29: =CE2 -> 612 | C29: =CF2 -> 609 | D29: =CG2 -> 560 | E29: =CE3 -> 54 | F29: =CF3 -> 36 | G29: =CG3 -> 23 | H29: =CE4 -> 380 | I29: =CF4 -> 379 | J29: =CG4 -> 376 | K29: =CE5 -> 28 | L29: =CF5 -> 23 | M29: =CG5 -> 0 | N29: =CE6 -> 23 | O29: =CF6 -> 12 | P29: =CG6 -> 0 | Q29: =CE7 -> 378 | R29: =CF7 -> 377 | S29: =CG7 -> 374 | T29: =CE8 -> 342 | U29: =CF8 -> 340 | V29: =CG8 -> 338 | W29: =CE9 -> 649 | X29: =CF9 -> 647 | Y29: =CG9 -> 646 | Z29: =CE10 -> 1292 | AA29: =CF10 -> 1282 | AB29: =CG10 -> 1279 | AC29: =CE11 -> 28 | AD29: =CF11 -> 17 | AE29: =CG11 -> 0 | AF29: =CE12 -> 28 | AG29: =CF12 -> 21 | AH29: =CG12 -> 960 | AI29: =CE13 -> 54 | AJ29: =CF13 -> 32 | AK29: =CG13 -> 0 | AL29: =CE14 -> 54 | AM29: =CF14 -> 22 | AN29: =CG14 -> 0 | AO29: =CE15 -> 312 | AP29: =CF15 -> 310 | AQ29: =CG15 -> 308 | AR29: =CE16 -> 561 | AS29: =CF16 -> 559 | AT29: =CG16 -> 557 | AU29: =CE17 -> 358 | AV29: =CF17 -> 355 | AW29: =CG17 -> 350 | AX29: =CE18 -> 1024 | AY29: =CF18 -> 1018 | AZ29: =CG18 -> 1016 | BA29: =CE19 -> 936 | BB29: =CF19 -> 231 | BC29: =CG19 -> 23 | BD29: =CE20 -> 780 | BE29: =CF20 -> 333 | BF29: =CG20 -> 233 | BG29: =CE21 -> 28 | BH29: =CF21 -> 16 | BI29: =CG21 -> 0 | BJ29: =CE22 -> 23 | BK29: =CF22 -> 12 | BL29: =CG22 -> 0 | BM29: =CE23 -> 797 | BN29: =CF23 -> 315 | BO29: =CG23 -> 196 | BP29: =CE24 -> 824 | BQ29: =CF24 -> 659 | BR29: =CG24 -> 585 | BS29: =CE25 -> 848 | BT29: =CF25 -> 843 | BU29: =CG25 -> 844 | BV29: =CE26 -> 28 | BW29: =CF26 -> 14 | BX29: =CG26 -> 0 | BY29: =CE27 -> 357 | BZ29: =CF27 -> 354 | CA29: =CG27 -> 352 | CB29: =CE28 -> 1061 | CC29: =CF28 -> 1065 | CD29: =CG28 -> 1062 | CE29: 0 | CF29: 0 | CG29: 0 | CH29: 28 | CI29: 12 | CJ29: 0 | CK29: 54 | CL29: 27 | CM29: 0 | CN29: 28 | CO29: 16 | CP29: 0 | CQ29: 556 | CR29: 550 | CS29: 547 | CT29: 28 | CU29: 18 | CV29: 0 | CW29: 28 | CX29: 14 | CY29: 0 | CZ29: 28 | DA29: 18 | DB29: 0 | DC29: 28 | DD29: 17 | DE29: 0 | DF29: 28 | DG29: 19 | DH29: 0 | DI29: 28 | DJ29: 17 | DK29: 0 | DL29: 28 | DM29: 18 | DN29: 0
A30: LAS PALMAS | B30: =CH2 -> 637 | C30: =CI2 -> 609 | D30: =CJ2 -> 536 | E30: =CH3 -> 0 | F30: =CI3 -> 0 | G30: =CJ3 -> 0 | H30: =CH4 -> 405 | I30: =CI4 -> 388 | J30: =CJ4 -> 378 | K30: =CH5 -> 0 | L30: =CI5 -> 0 | M30: =CJ5 -> 0 | N30: =CH6 -> 0 | O30: =CI6 -> 0 | P30: =CJ6 -> 0 | Q30: =CH7 -> 403 | R30: =CI7 -> 387 | S30: =CJ7 -> 375 | T30: =CH8 -> 367 | U30: =CI8 -> 351 | V30: =CJ8 -> 339 | W30: =CH9 -> 674 | X30: =CI9 -> 659 | Y30: =CJ9 -> 646 | Z30: =CH10 -> 1307 | AA30: =CI10 -> 1291 | AB30: =CJ10 -> 1279 | AC30: =CH11 -> 0 | AD30: =CI11 -> 0 | AE30: =CJ11 -> 0 | AF30: =CH12 -> 0 | AG30: =CI12 -> 0 | AH30: =CJ12 -> 0 | AI30: =CH13 -> 0 | AJ30: =CI13 -> 0 | AK30: =CJ13 -> 0 | AL30: =CH14 -> 0 | AM30: =CI14 -> 0 | AN30: =CJ14 -> 0 | AO30: =CH15 -> 337 | AP30: =CI15 -> 322 | AQ30: =CJ15 -> 309 | AR30: =CH16 -> 586 | AS30: =CI16 -> 571 | AT30: =CJ16 -> 559 | AU30: =CH17 -> 377 | AV30: =CI17 -> 361 | AW30: =CJ17 -> 350 | AX30: =CH18 -> 1043 | AY30: =CI18 -> 1028 | AZ30: =CJ18 -> 1016 | BA30: =CH19 -> 205 | BB30: =CI19 -> 105 | BC30: =CJ19 -> 0 | BD30: =CH20 -> 814 | BE30: =CI20 -> 308 | BF30: =CJ20 -> 210 | BG30: =CH21 -> 0 | BH30: =CI21 -> 0 | BI30: =CJ21 -> 0 | BJ30: =CH22 -> 0 | BK30: =CI22 -> 0 | BL30: =CJ22 -> 0 | BM30: =CH23 -> 818 | BN30: =CI23 -> 292 | BO30: =CJ23 -> 173 | BP30: =CH24 -> 849 | BQ30: =CI24 -> 631 | BR30: =CJ24 -> 562 | BS30: =CH25 -> 844 | BT30: =CI25 -> 602 | BU30: =CJ25 -> 533 | BV30: =CH26 -> 0 | BW30: =CI26 -> 0 | BX30: =CJ26 -> 0 | BY30: =CH27 -> 379 | BZ30: =CI27 -> 364 | CA30: =CJ27 -> 352 | CB30: =CH28 -> 1088 | CC30: =CI28 -> 1073 | CD30: =CJ28 -> 1063 | CE30: =CH29 -> 28 | CF30: =CI29 -> 12 | CG30: =CJ29 -> 0 | CH30: 0 | CI30: 0 | CJ30: 0 | CK30: 0 | CL30: 0 | CM30: 0 | CN30: 0 | CO30: 0 | CP30: 0 | CQ30: 569 | CR30: 559 | CS30: 548 | CT30: 0 | CU30: 0 | CV30: 0 | CW30: 0 | CX30: 0 | CY30: 0 | CZ30: 0 | DA30: 0 | DB30: 0 | DC30: 0 | DD30: 0 | DE30: 0 | DF30: 0 | DG30: 0 | DH30: 0 | DI30: 0 | DJ30: 0 | DK30: 0 | DL30: 0 | DM30: 0 | DN30: 0
A31: SANTANDER | B31: =CK2 -> 637 | C31: =CL2 -> 609 | D31: =CM2 -> 536 | E31: =CK3 -> 0 | F31: =CL3 -> 0 | G31: =CM3 -> 0 | H31: =CK4 -> 405 | I31: =CL4 -> 388 | J31: =CM4 -> 378 | K31: =CK5 -> 0 | L31: =CL5 -> 0 | M31: =CM5 -> 0 | N31: =CK6 -> 0 | O31: =CL6 -> 0 | P31: =CM6 -> 0 | Q31: =CK7 -> 403 | R31: =CL7 -> 386 | S31: =CM7 -> 375 | T31: =CK8 -> 367 | U31: =CL8 -> 351 | V31: =CM8 -> 339 | W31: =CK9 -> 674 | X31: =CL9 -> 659 | Y31: =CM9 -> 646 | Z31: =CK10 -> 1307 | AA31: =CL10 -> 1291 | AB31: =CM10 -> 1279 | AC31: =CK11 -> 0 | AD31: =CL11 -> 0 | AE31: =CM11 -> 0 | AF31: =CK12 -> 0 | AG31: =CL12 -> 0 | AH31: =CM12 -> 0 | AI31: =CK13 -> 0 | AJ31: =CL13 -> 0 | AK31: =CM13 -> 0 | AL31: =CK14 -> 0 | AM31: =CL14 -> 0 | AN31: =CM14 -> 0 | AO31: =CK15 -> 337 | AP31: =CL15 -> 321 | AQ31: =CM15 -> 309 | AR31: =CK16 -> 586 | AS31: =CL16 -> 573 | AT31: =CM16 -> 559 | AU31: =CK17 -> 377 | AV31: =CL17 -> 363 | AW31: =CM17 -> 350 | AX31: =CK18 -> 1043 | AY31: =CL18 -> 1029 | AZ31: =CM18 -> 1016 | BA31: =CK19 -> 961 | BB31: =CL19 -> 218 | BC31: =CM19 -> 0 | BD31: =CK20 -> 783 | BE31: =CL20 -> 307 | BF31: =CM20 -> 210 | BG31: =CK21 -> 0 | BH31: =CL21 -> 0 | BI31: =CM21 -> 0 | BJ31: =CK22 -> 0 | BK31: =CL22 -> 0 | BL31: =CM22 -> 0 | BM31: =CK23 -> 818 | BN31: =CL23 -> 292 | BO31: =CM23 -> 173 | BP31: =CK24 -> 837 | BQ31: =CL24 -> 632 | BR31: =CM24 -> 562 | BS31: =CK25 -> 855 | BT31: =CL25 -> 602 | BU31: =CM25 -> 533 | BV31: =CK26 -> 0 | BW31: =CL26 -> 0 | BX31: =CM26 -> 0 | BY31: =CK27 -> 376 | BZ31: =CL27 -> 365 | CA31: =CM27 -> 367 | CB31: =CK28 -> 1083 | CC31: =CL28 -> 1072 | CD31: =CM28 -> 1063 | CE31: =CK29 -> 54 | CF31: =CL29 -> 27 | CG31: =CM29 -> 0 | CH31: =CK30 -> 0 | CI31: =CL30 -> 0 | CJ31: =CM30 -> 0 | CK31: 0 | CL31: 0 | CM31: 0 | CN31: 0 | CO31: 0 | CP31: 0 | CQ31: 575 | CR31: 562 | CS31: 548 | CT31: 0 | CU31: 0 | CV31: 0 | CW31: 0 | CX31: 0 | CY31: 0 | CZ31: 0 | DA31: 0 | DB31: 0 | DC31: 0 | DD31: 0 | DE31: 0 | DF31: 0 | DG31: 0 | DH31: 0 | DI31: 0 | DJ31: 0 | DK31: 0 | DL31: 0 | DM31: 0 | DN31: 0
A32: VIGO | B32: =CN2 -> 637 | C32: =CO2 -> 609 | D32: =CP2 -> 536 | E32: =CN3 -> 0 | F32: =CO3 -> 0 | G32: =CP3 -> 0 | H32: =CN4 -> 405 | I32: =CO4 -> 388 | J32: =CP4 -> 378 | K32: =CN5 -> 0 | L32: =CO5 -> 0 | M32: =CP5 -> 0 | N32: =CN6 -> 0 | O32: =CO6 -> 0 | P32: =CP6 -> 0 | Q32: =CN7 -> 403 | R32: =CO7 -> 385 | S32: =CP7 -> 375 | T32: =CN8 -> 367 | U32: =CO8 -> 351 | V32: =CP8 -> 339 | W32: =CN9 -> 674 | X32: =CO9 -> 659 | Y32: =CP9 -> 646 | Z32: =CN10 -> 1307 | AA32: =CO10 -> 1292 | AB32: =CP10 -> 1279 | AC32: =CN11 -> 0 | AD32: =CO11 -> 0 | AE32: =CP11 -> 0 | AF32: =CN12 -> 0 | AG32: =CO12 -> 0 | AH32: =CP12 -> 0 | AI32: =CN13 -> 0 | AJ32: =CO13 -> 0 | AK32: =CP13 -> 0 | AL32: =CN14 -> 0 | AM32: =CO14 -> 0 | AN32: =CP14 -> 0 | AO32: =CN15 -> 337 | AP32: =CO15 -> 320 | AQ32: =CP15 -> 309 | AR32: =CN16 -> 586 | AS32: =CO16 -> 572 | AT32: =CP16 -> 559 | AU32: =CN17 -> 377 | AV32: =CO17 -> 362 | AW32: =CP17 -> 350 | AX32: =CN18 -> 1043 | AY32: =CO18 -> 1028 | AZ32: =CP18 -> 1016 | BA32: =CN19 -> 205 | BB32: =CO19 -> 118 | BC32: =CP19 -> 0 | BD32: =CN20 -> 788 | BE32: =CO20 -> 310 | BF32: =CP20 -> 210 | BG32: =CN21 -> 0 | BH32: =CO21 -> 0 | BI32: =CP21 -> 0 | BJ32: =CN22 -> 0 | BK32: =CO22 -> 0 | BL32: =CP22 -> 0 | BM32: =CN23 -> 818 | BN32: =CO23 -> 287 | BO32: =CP23 -> 173 | BP32: =CN24 -> 835 | BQ32: =CO24 -> 631 | BR32: =CP24 -> 562 | BS32: =CN25 -> 858 | BT32: =CO25 -> 602 | BU32: =CP25 -> 543 | BV32: =CN26 -> 0 | BW32: =CO26 -> 0 | BX32: =CP26 -> 0 | BY32: =CN27 -> 378 | BZ32: =CO27 -> 368 | CA32: =CP27 -> 353 | CB32: =CN28 -> 1085 | CC32: =CO28 -> 1072 | CD32: =CP28 -> 1061 | CE32: =CN29 -> 28 | CF32: =CO29 -> 16 | CG32: =CP29 -> 0 | CH32: =CN30 -> 0 | CI32: =CO30 -> 0 | CJ32: =CP30 -> 0 | CK32: =CN31 -> 0 | CL32: =CO31 -> 0 | CM32: =CP31 -> 0 | CN32: 0 | CO32: 0 | CP32: 0 | CQ32: 575 | CR32: 561 | CS32: 548 | CT32: 0 | CU32: 0 | CV32: 0 | CW32: 0 | CX32: 0 | CY32: 0 | CZ32: 0 | DA32: 0 | DB32: 0 | DC32: 0 | DD32: 0 | DE32: 0 | DF32: 0 | DG32: 0 | DH32: 0 | DI32: 0 | DJ32: 0 | DK32: 0 | DL32: 0 | DM32: 0 | DN32: 0
A33: EMDEN | B33: =CQ2 -> 135 | C33: =CR2 -> 130 | D33: =CS2 -> 127 | E33: =CQ3 -> 575 | F33: =CR3 -> 549 | G33: =CS3 -> 505 | H33: =CQ4 -> 190 | I33: =CR4 -> 189 | J33: =CS4 -> 188 | K33: =CQ5 -> 575 | L33: =CR5 -> 559 | M33: =CS5 -> 548 | N33: =CQ6 -> 555 | O33: =CR6 -> 548 | P33: =CS6 -> 505 | Q33: =CQ7 -> 261 | R33: =CR7 -> 261 | S33: =CS7 -> 261 | T33: =CQ8 -> 234 | U33: =CR8 -> 234 | V33: =CS8 -> 234 | W33: =CQ9 -> 164 | X33: =CR9 -> 164 | Y33: =CS9 -> 164 | Z33: =CQ10 -> 797 | AA33: =CR10 -> 797 | AB33: =CS10 -> 797 | AC33: =CQ11 -> 575 | AD33: =CR11 -> 561 | AE33: =CS11 -> 548 | AF33: =CQ12 -> 576 | AG33: =CR12 -> 548 | AH33: =CS12 -> 505 | AI33: =CQ13 -> 575 | AJ33: =CR13 -> 548 | AK33: =CS13 -> 505 | AL33: =CQ14 -> 575 | AM33: =CR14 -> 562 | AN33: =CS14 -> 548 | AO33: =CQ15 -> 266 | AP33: =CR15 -> 266 | AQ33: =CS15 -> 266 | AR33: =CQ16 -> 327 | AS33: =CR16 -> 327 | AT33: =CS16 -> 327 | AU33: =CQ17 -> 236 | AV33: =CR17 -> 236 | AW33: =CS17 -> 236 | AX33: =CQ18 -> 534 | AY33: =CR18 -> 534 | AZ33: =CS18 -> 534 | BA33: =CQ19 -> 542 | BB33: =CR19 -> 542 | BC33: =CS19 -> 542 | BD33: =CQ20 -> 378 | BE33: =CR20 -> 378 | BF33: =CS20 -> 378 | BG33: =CQ21 -> 575 | BH33: =CR21 -> 561 | BI33: =CS21 -> 549 | BJ33: =CQ22 -> 575 | BK33: =CR22 -> 548 | BL33: =CS22 -> 505 | BM33: =CQ23 -> 395 | BN33: =CR23 -> 395 | BO33: =CS23 -> 395 | BP33: =CQ24 -> 340 | BQ33: =CR24 -> 340 | BR33: =CS24 -> 340 | BS33: =CQ25 -> 360 | BT33: =CR25 -> 360 | BU33: =CS25 -> 360 | BV33: =CQ26 -> 575 | BW33: =CR26 -> 566 | BX33: =CS26 -> 552 | BY33: =CQ27 -> 303 | BZ33: =CR27 -> 303 | CA33: =CS27 -> 303 | CB33: =CQ28 -> 579 | CC33: =CR28 -> 579 | CD33: =CS28 -> 579 | CE33: =CQ29 -> 556 | CF33: =CR29 -> 550 | CG33: =CS29 -> 547 | CH33: =CQ30 -> 569 | CI33: =CR30 -> 559 | CJ33: =CS30 -> 548 | CK33: =CQ31 -> 575 | CL33: =CR31 -> 562 | CM33: =CS31 -> 548 | CN33: =CQ32 -> 575 | CO33: =CR32 -> 561 | CP33: =CS32 -> 548 | CQ33: 0 | CR33: 0 | CS33: 0 | CT33: 575 | CU33: 558 | CV33: 549 | CW33: 575 | CX33: 563 | CY33: 549 | CZ33: 571 | DA33: 561 | DB33: 548 | DC33: 573 | DD33: 564 | DE33: 550 | DF33: 570 | DG33: 559 | DH33: 548 | DI33: 573 | DJ33: 560 | DK33: 549 | DL33: 571 | DM33: 560 | DN33: 549
A34: CADIZ | B34: =CT2 -> 637 | C34: =CU2 -> 609 | D34: =CV2 -> 536 | E34: =CT3 -> 0 | F34: =CU3 -> 0 | G34: =CV3 -> 0 | H34: =CT4 -> 405 | I34: =CU4 -> 388 | J34: =CV4 -> 378 | K34: =CT5 -> 0 | L34: =CU5 -> 0 | M34: =CV5 -> 0 | N34: =CT6 -> 0 | O34: =CU6 -> 0 | P34: =CV6 -> 0 | Q34: =CT7 -> 403 | R34: =CU7 -> 387 | S34: =CV7 -> 375 | T34: =CT8 -> 367 | U34: =CU8 -> 351 | V34: =CV8 -> 339 | W34: =CT9 -> 674 | X34: =CU9 -> 658 | Y34: =CV9 -> 646 | Z34: =CT10 -> 1307 | AA34: =CU10 -> 1291 | AB34: =CV10 -> 1279 | AC34: =CT11 -> 0 | AD34: =CU11 -> 0 | AE34: =CV11 -> 0 | AF34: =CT12 -> 0 | AG34: =CU12 -> 0 | AH34: =CV12 -> 0 | AI34: =CT13 -> 0 | AJ34: =CU13 -> 0 | AK34: =CV13 -> 0 | AL34: =CT14 -> 0 | AM34: =CU14 -> 0 | AN34: =CV14 -> 0 | AO34: =CT15 -> 337 | AP34: =CU15 -> 321 | AQ34: =CV15 -> 309 | AR34: =CT16 -> 586 | AS34: =CU16 -> 571 | AT34: =CV16 -> 559 | AU34: =CT17 -> 377 | AV34: =CU17 -> 362 | AW34: =CV17 -> 350 | AX34: =CT18 -> 1043 | AY34: =CU18 -> 1027 | AZ34: =CV18 -> 1016 | BA34: =CT19 -> 195 | BB34: =CU19 -> 109 | BC34: =CV19 -> 0 | BD34: =CT20 -> 790 | BE34: =CU20 -> 304 | BF34: =CV20 -> 210 | BG34: =CT21 -> 0 | BH34: =CU21 -> 0 | BI34: =CV21 -> 0 | BJ34: =CT22 -> 0 | BK34: =CU22 -> 0 | BL34: =CV22 -> 0 | BM34: =CT23 -> 799 | BN34: =CU23 -> 292 | BO34: =CV23 -> 173 | BP34: =CT24 -> 835 | BQ34: =CU24 -> 633 | BR34: =CV24 -> 562 | BS34: =CT25 -> 856 | BT34: =CU25 -> 605 | BU34: =CV25 -> 533 | BV34: =CT26 -> 0 | BW34: =CU26 -> 0 | BX34: =CV26 -> 0 | BY34: =CT27 -> 376 | BZ34: =CU27 -> 364 | CA34: =CV27 -> 354 | CB34: =CT28 -> 1088 | CC34: =CU28 -> 1072 | CD34: =CV28 -> 1061 | CE34: =CT29 -> 28 | CF34: =CU29 -> 18 | CG34: =CV29 -> 0 | CH34: =CT30 -> 0 | CI34: =CU30 -> 0 | CJ34: =CV30 -> 0 | CK34: =CT31 -> 0 | CL34: =CU31 -> 0 | CM34: =CV31 -> 0 | CN34: =CT32 -> 0 | CO34: =CU32 -> 0 | CP34: =CV32 -> 0 | CQ34: =CT33 -> 575 | CR34: =CU33 -> 558 | CS34: =CV33 -> 549 | CT34: 0 | CU34: 0 | CV34: 0 | CW34: 0 | CX34: 0 | CY34: 0 | CZ34: 0 | DA34: 0 | DB34: 0 | DC34: 0 | DD34: 0 | DE34: 0 | DF34: 0 | DG34: 0 | DH34: 0 | DI34: 0 | DJ34: 0 | DK34: 0 | DL34: 0 | DM34: 0 | DN34: 0
A35: LA SPEZIA | B35: =CW2 -> 637 | C35: =CX2 -> 609 | D35: =CY2 -> 536 | E35: =CW3 -> 0 | F35: =CX3 -> 0 | G35: =CY3 -> 0 | H35: =CW4 -> 405 | I35: =CX4 -> 387 | J35: =CY4 -> 378 | K35: =CW5 -> 0 | L35: =CX5 -> 0 | M35: =CY5 -> 0 | N35: =CW6 -> 0 | O35: =CX6 -> 0 | P35: =CY6 -> 0 | Q35: =CW7 -> 403 | R35: =CX7 -> 385 | S35: =CY7 -> 375 | T35: =CW8 -> 367 | U35: =CX8 -> 351 | V35: =CY8 -> 339 | W35: =CW9 -> 674 | X35: =CX9 -> 658 | Y35: =CY9 -> 646 | Z35: =CW10 -> 1307 | AA35: =CX10 -> 1290 | AB35: =CY10 -> 1279 | AC35: =CW11 -> 0 | AD35: =CX11 -> 0 | AE35: =CY11 -> 0 | AF35: =CW12 -> 0 | AG35: =CX12 -> 0 | AH35: =CY12 -> 0 | AI35: =CW13 -> 0 | AJ35: =CX13 -> 0 | AK35: =CY13 -> 0 | AL35: =CW14 -> 0 | AM35: =CX14 -> 0 | AN35: =CY14 -> 0 | AO35: =CW15 -> 337 | AP35: =CX15 -> 322 | AQ35: =CY15 -> 309 | AR35: =CW16 -> 586 | AS35: =CX16 -> 571 | AT35: =CY16 -> 559 | AU35: =CW17 -> 377 | AV35: =CX17 -> 362 | AW35: =CY17 -> 350 | AX35: =CW18 -> 1043 | AY35: =CX18 -> 1027 | AZ35: =CY18 -> 1016 | BA35: =CW19 -> 961 | BB35: =CX19 -> 301 | BC35: =CY19 -> 0 | BD35: =CW20 -> 786 | BE35: =CX20 -> 306 | BF35: =CY20 -> 210 | BG35: =CW21 -> 0 | BH35: =CX21 -> 0 | BI35: =CY21 -> 0 | BJ35: =CW22 -> 0 | BK35: =CX22 -> 0 | BL35: =CY22 -> 0 | BM35: =CW23 -> 806 | BN35: =CX23 -> 284 | BO35: =CY23 -> 173 | BP35: =CW24 -> 839 | BQ35: =CX24 -> 631 | BR35: =CY24 -> 562 | BS35: =CW25 -> 869 | BT35: =CX25 -> 855 | BU35: =CY25 -> 842 | BV35: =CW26 -> 0 | BW35: =CX26 -> 0 | BX35: =CY26 -> 0 | BY35: =CW27 -> 374 | BZ35: =CX27 -> 360 | CA35: =CY27 -> 353 | CB35: =CW28 -> 1085 | CC35: =CX28 -> 1073 | CD35: =CY28 -> 1061 | CE35: =CW29 -> 28 | CF35: =CX29 -> 14 | CG35: =CY29 -> 0 | CH35: =CW30 -> 0 | CI35: =CX30 -> 0 | CJ35: =CY30 -> 0 | CK35: =CW31 -> 0 | CL35: =CX31 -> 0 | CM35: =CY31 -> 0 | CN35: =CW32 -> 0 | CO35: =CX32 -> 0 | CP35: =CY32 -> 0 | CQ35: =CW33 -> 575 | CR35: =CX33 -> 563 | CS35: =CY33 -> 549 | CT35: =CW34 -> 0 | CU35: =CX34 -> 0 | CV35: =CY34 -> 0 | CW35: 0 | CX35: 0 | CY35: 0 | CZ35: 0 | DA35: 0 | DB35: 0 | DC35: 0 | DD35: 0 | DE35: 0 | DF35: 0 | DG35: 0 | DH35: 0 | DI35: 0 | DJ35: 0 | DK35: 0 | DL35: 0 | DM35: 0 | DN35: 0
